Workbook
Name Prix_Base_Primera: 'Lot 4 - BPU Drom-Com'!$AC$1111
Name Prix_Base_Primera: 'Lot 4 - BPU Location'!$AA$1111
Name Prix_Base_Primera: 'Lot 4 - Bordereau de prix'!$AC$1112
Name Prix_Cache_HF20: 'Lot 4 - BPU Drom-Com'!$AC$1091
Name Prix_Cache_HF20: 'Lot 4 - BPU Location'!$AA$1091
Name Prix_Cache_HF20: 'Lot 4 - Bordereau de prix'!$AC$1092
Name Prix_Cache_HF20H: 'Lot 4 - BPU Drom-Com'!$AC$1074
Name Prix_Cache_HF20H: 'Lot 4 - BPU Location'!$AA$1074
Name Prix_Cache_HF20H: 'Lot 4 - Bordereau de prix'!$AC$1075
Name Prix_Cache_HF40: 'Lot 4 - BPU Drom-Com'!$AC$1030
Name Prix_Cache_HF40: 'Lot 4 - BPU Location'!$AA$1030
Name Prix_Cache_HF40: 'Lot 4 - Bordereau de prix'!$AC$1031
Name Prix_chassis_A6010: 'Lot 4 - BPU Drom-Com'!$O$1056
Name Prix_chassis_A6010: 'Lot 4 - BPU Location'!$O$1056
Name Prix_chassis_A6010: 'Lot 4 - Bordereau de prix'!$O$1057
Name Prix_Chassis_HF20: 'Lot 4 - BPU Drom-Com'!$AC$1017
Name Prix_Chassis_HF20: 'Lot 4 - BPU Location'!$AA$1017
Name Prix_Chassis_HF20: 'Lot 4 - Bordereau de prix'!$AC$1018
Name Prix_chassis_HF40: 'Lot 4 - BPU Drom-Com'!$AC$1029
Name Prix_chassis_HF40: 'Lot 4 - BPU Location'!$AA$1029
Name Prix_chassis_HF40: 'Lot 4 - Bordereau de prix'!$AC$1030
Name Prix_Ctrl_A9K: 'Lot 4 - BPU Drom-Com'!$AC$1073
Name Prix_Ctrl_A9K: 'Lot 4 - BPU Location'!$AA$1073
Name Prix_Ctrl_A9K: 'Lot 4 - Bordereau de prix'!$AC$1074
Name Prix_Ctrl_Primera: 'Lot 4 - BPU Drom-Com'!$AC$1043
Name Prix_Ctrl_Primera: 'Lot 4 - BPU Location'!$AA$1043
Name Prix_Ctrl_Primera: 'Lot 4 - Bordereau de prix'!$AC$1044
Name Prix_diques_23TB_A6k: 'Lot 4 - BPU Drom-Com'!$AC$1060
Name Prix_diques_23TB_A6k: 'Lot 4 - BPU Location'!$AA$1060
Name Prix_diques_23TB_A6k: 'Lot 4 - Bordereau de prix'!$AC$1061
Name Prix_Disques_21TB_HF20: 'Lot 4 - BPU Drom-Com'!$AC$1018
Name Prix_Disques_21TB_HF20: 'Lot 4 - BPU Location'!$AA$1018
Name Prix_Disques_21TB_HF20: 'Lot 4 - Bordereau de prix'!$AC$1019
Name Prix_Disques_42TB_HF40: 'Lot 4 - BPU Drom-Com'!$AC$1032
Name Prix_Disques_42TB_HF40: 'Lot 4 - BPU Location'!$AA$1032
Name Prix_Disques_42TB_HF40: 'Lot 4 - Bordereau de prix'!$AC$1033
Name Prix_Power_Alletra6k: 'Lot 4 - BPU Drom-Com'!$AC$1062
Name Prix_Power_Alletra6k: 'Lot 4 - BPU Location'!$AA$1062
Name Prix_Power_Alletra6k: 'Lot 4 - Bordereau de prix'!$AC$1063
Name Prix_SSD_Primera: 'Lot 4 - BPU Drom-Com'!$AC$1044
Name Prix_SSD_Primera: 'Lot 4 - BPU Location'!$AA$1044
Name Prix_SSD_Primera: 'Lot 4 - Bordereau de prix'!$AC$1045
Name Prix_Support_11TB_HF20H: 'Lot 4 - BPU Drom-Com'!$AC$1010
Name Prix_Support_11TB_HF20H: 'Lot 4 - BPU Location'!$AA$1010
Name Prix_Support_11TB_HF20H: 'Lot 4 - Bordereau de prix'!$AC$1011
Name Prix_Support_21TB_HF20: 'Lot 4 - BPU Drom-Com'!$AC$1024
Name Prix_Support_21TB_HF20: 'Lot 4 - BPU Location'!$AA$1024
Name Prix_Support_21TB_HF20: 'Lot 4 - Bordereau de prix'!$AC$1025
Name Prix_Support_42TB_HF40: 'Lot 4 - BPU Drom-Com'!$AC$1038
Name Prix_Support_42TB_HF40: 'Lot 4 - BPU Location'!$AA$1038
Name Prix_Support_42TB_HF40: 'Lot 4 - Bordereau de prix'!$AC$1039
Name Prix_Support_Alletra610: 'Lot 4 - BPU Drom-Com'!$O$1067
Name Prix_Support_Alletra610: 'Lot 4 - BPU Location'!$O$1067
Name Prix_Support_Alletra610: 'Lot 4 - Bordereau de prix'!$O$1068
Name Prix_Support_Base_Primera: 'Lot 4 - BPU Drom-Com'!$AC$1049
Name Prix_Support_Base_Primera: 'Lot 4 - BPU Location'!$AA$1049
Name Prix_Support_Base_Primera: 'Lot 4 - Bordereau de prix'!$AC$1050
Name Prix_Support_cache_HF20: 'Lot 4 - BPU Drom-Com'!$AC$1025
Name Prix_Support_cache_HF20: 'Lot 4 - BPU Location'!$AA$1025
Name Prix_Support_cache_HF20: 'Lot 4 - Bordereau de prix'!$AC$1026

Sheet Suivi de version
B2: Mise à jour Février 2022
B3: o Version initiale validée le 10/09/2021
B4: N1 V2 | C4: Ajoût numéros de références manquantes sur Descriptifs et prix existants
C5: Baisses de prix sur 2 références suites à erreurs typographiques
C6: Ajout (sans impact prix) de references logisitique de prises de rdv commandes sur toutes les configurations
C7: Correction de commentaires et descriptif suite à erreurs typographiques
C8: Ajout de passage de HDD vers SSD
A9: 44497 | B9: V3 | C9: Ajoût numéros de références manquantes sur Descriptifs et prix existants
C10: Baisse de prix sur 1 référence suite à erreur typographique
C11: Hausse de prix sur 1 référence suite à erreur typographique
C12: Changement de références logistique de l'interieur à quai/porte
C13: Ajout de passage livraison à l'interieur à 0€
C14: Ajout des references de prise de rdv a 1€
C15: Ajout des references livraison a l'etage a 1€
C16: Baisse de 2€ sur les configuration pour refleter ce surcout eventuel
C17: Suppression du cordon electrique par defaut
C18: Ajout des cordons 0,7m et 2m à 1€
C19: Baisse de 1€ sur les configuration pour refleter ce surcout eventuel
C20: Ajout des serveurs Intel Gen10+
C21: Ajout des serveurs AMD Gen10 +V2
... C28: Suppressions des ajouts impossible (cad avec passage uniquement)
A30: 44623 | B30: V4 | C30: Ajoût numéros de références manquantes sur Descriptifs et prix existants
C31: Correction de prix d'ajout ou passage pour respect prix passage (prix ajout - prix passage)
C32: Ajout de lignes support Nimble manquantes
C33: Ajout/Suppression/Mise à jour de reference SSD/Nvme obsoletes d'ici 3 mois
C34: Integration des SKUS HPE VMWare EDUC
C35: Integration des SKUS HPE MS EDUC
C36: Integration des SKUS Support 6 / 7 ans sur certaines references produits
C37: Ajout CPUs
C38: Suppression : Categorie 2 Options pour mutualisation
C39: Equilibrage de la ram des bundle par remplacement de barrette DIMM 16Go/32Go par 32Go/64Go avec répercution prix passage sur bundle
C40: Simplification des configurations Apollo 6500 avec configurations non éclatés (chassis et serveur) : prix final respecté avec logique ajout/passage
C41: Ajout Chassis Apollo Gen10+ Intel avec suppression de passage AMD avec Intel : prix final respecté avec logique ajout/passage
C42: Suppression temporaire des options sans garanti 5 ans embarqué (Nimble, Primera, Commutateurs,…)
A44: 44704 | B44: v5 | C44: Suppression des Ctrl RAID + disques durs des configurations (dégression des prix en conséquence)
C45: Ajout des rails kits dans les configurations (prise en compte dans prix bundle)
C46: Ajout derniers serveurs Gen10+ (ML30, DL20, Apollo 4200)
C47: Ajout Stockage Alletra, Qumulo
C48: Ajout références produit générique pour simplification BPU
C49: Ajout références stockage et réseau avec 5 ans intégrés
...

Sheet Lot 4 - Bordereau de prix
A4: Bordereau de prix unitaires
A6: DésignationDescription des matériels | B6: Référence constructeur (le cas échéant) | C6: HPE SKU | D6: Quantités | E6: Column1 | F6: TARIFS en €HT | G6: Ancien Tarif | H6: Delta
A7: CATEGORIE 1 : Serveurs Edge ou Standard
A8: Désignation/Description des matériels | B8: Référence constructeur (le cas échéant) | C8: Numéro de référence | D8: Quantités | F8: TARIFS en €HT | G8: TARIFS en €HT
A9: Cat1 Conf1 Microserver | B9: HPE ProLiant MicroServer Gen10+ | C9: P16005-421 | F9: 488.24 | G9: 488.24 | H9: =IF(ISNUMBER(F9),ROUND(F9-G9,2),"") -> 0
A10: Serveur tour Ultra Micro mono-socket | B10: HPE ProLiant MicroServer Gen10 Plus G5420 2-core 1P 8GB-U S100i 4LFF-NHP 180W External PS Server | C10: P16005-421 | D10: 1 | H10: =IF(ISNUMBER(F10),ROUND(F10-G10,2),"")
A11: 1 disque de 1 To 6G SATA 7.2K 3,5 pouces (LFF) Non Hot Plug | B11: HPE 1TB SATA 6G Entry 7.2K LFF (3.5in) RW 1yr Wty HDD | C11: 843266-B21 | D11: 1 | H11: =IF(ISNUMBER(F11),ROUND(F11-G11,2),"")
A12: Kit pour carte d'administration HPE iLO | B12: HPE MicroServer Gen10 Plus iLO Enablement Kit | C12: P13788-B21 | D12: 1 | H12: =IF(ISNUMBER(F12),ROUND(F12-G12,2),"")
A13: Carte d'administration HPE iLO avec API RESTful compatible IPMI v2.0 et Redfish. Licence en version Advanced avec toutes les options activées | B13: HPE iLO Advanced 1-server License with 1yr Support on iLO Licensed Features | C13: 512485-B21 | D13: 1 | H13: =IF(ISNUMBER(F13),ROUND(F13-G13,2),"")
A14: Livraison devant la porte | B14: Livraison devant la porte | C14: AC114A | D14: 1 | H14: =IF(ISNUMBER(F14),ROUND(F14-G14,2),"")
A15: Garantie 5 ans J+1 | B15: HPE 5Y Tech Care Basic Service | C15: HU4B2A5 | D15: 1 | H15: =IF(ISNUMBER(F15),ROUND(F15-G15,2),"")
A16: Garantie 5 ans J+1 ILO | B16: HPE iLO AdvPack NonBL Support | C16: HU4B2A5#7X4 | D16: 1 | H16: =IF(ISNUMBER(F16),ROUND(F16-G16,2),"")
A17: Garantie 5 ans J+1 châssis | B17: HPE Microserver Gen10 Plus Support | C17: HU4B2A5#YKX | D17: 1 | H17: =IF(ISNUMBER(F17),ROUND(F17-G17,2),"")
H18: =IF(ISNUMBER(F18),ROUND(F18-G18,2),"")
A19: Cat1 Conf5 DL20 Gen10 plus | B19: HPE ProLiant DL20 Gen10+ | C19: P44109-B21 | F19: 302.89 | G19: 302.89 | H19: =IF(ISNUMBER(F19),ROUND(F19-G19,2),"") -> 0
A20: Serveur rack standard 1U mono-socket INTEL | B20: HPE DL20 Gen10+ 2LFF NHP CTO Svr | C20: P44109-B21 | D20: 1 | H20: =IF(ISNUMBER(F20),ROUND(F20-G20,2),"")
A21: Processeur 64 bits Intel Xeon E-2314 (2,8 GHz de base / 4,50 Ghz Turbo / 4 cœurs / 4 threads / 8 Mo Smart Cache / 65 W PDT | B21: Intel Xeon E-2314 2.8GHz 4-core 65W FIO Processor for HPE | C21: P45248-B21 | D21: 1 | H21: =IF(ISNUMBER(F21),ROUND(F21-G21,2),"")
A22: 1 barrette mémoire HPE Standard DDR4 2666 MHz UDIMM de 16 Go (soit 4 Go ECC par cœur) | B22: HPE 16GB (1x16GB) Single Rank x8 DDR4-3200 CAS-22-22-22 Unbuffered Standard Memory Kit | C22: P43019-B21 | D22: 1 | H22: =IF(ISNUMBER(F22),ROUND(F22-G22,2),"")
A23: 1 cage pour emplacement PCI | B23: HPE ProLiant DL20 Gen10 Plus x8/x8 LP FIO Riser Kit | C23: P46114-B21 | D23: 1 | H23: =IF(ISNUMBER(F23),ROUND(F23-G23,2),"")
A24: Alimentation 290W certifiée 80Plus Platinium | B24: HPE DL20 Gen10 Plat 290W FIO PSU Kit | C24: P21649-B21 | D24: 1 | H24: =IF(ISNUMBER(F24),ROUND(F24-G24,2),"")
A25: Carte d'administration HPE iLO avec API RESTful compatible IPMI v2.0 et Redfish. Licence en version Advanced avec toutes les options activées | B25: HPE iLO Adv 1-svr Lic 1yr Support | C25: 512485-B21 | D25: 1 | H25: =IF(ISNUMBER(F25),ROUND(F25-G25,2),"")
A26: Suppresion du cable electrique par defaut | B26: HPE Remove Standard Power Cords | C26: 469774-409 | D26: 1 | H26: =IF(ISNUMBER(F26),ROUND(F26-G26,2),"")
A27: 1 kit de rail pour rack | B27: HPE 1U Short Friction Rail Kit | C27: 775612-B21 | D27: 1 | H27: =IF(ISNUMBER(F27),ROUND(F27-G27,2),"")
A28: Livraison devant la porte | B28: Livraison devant la porte | C28: AC111A | D28: 1 | H28: =IF(ISNUMBER(F28),ROUND(F28-G28,2),"")
A29: Garantie 5 ans J+1 | B29: HPE 5Y Tech Care Basic Service | C29: HU4B2A5 | D29: 1 | H29: =IF(ISNUMBER(F29),ROUND(F29-G29,2),"")
A30: Garantie 5 ans J+1 ILO | B30: HPE iLO AdvPack NonBL Support | C30: HU4B2A5#7X4 | D30: 1 | H30: =IF(ISNUMBER(F30),ROUND(F30-G30,2),"")
A31: Garantie 5 ans J+1 châssis | B31: HPE ProLiant DL20 Gen10+ Support | C31: HU4B2A5#ZX1 | D31: 1 | H31: =IF(ISNUMBER(F31),ROUND(F31-G31,2),"")
H32: =IF(ISNUMBER(F32),ROUND(F32-G32,2),"")
A33: Cat1 Conf2 DL325 Gen10 plus | B33: HPE ProLiant DL325 Gen10+ | C33: P18606-B21 | F33: 674.1 | G33: 674.1 | H33: =IF(ISNUMBER(F33),ROUND(F33-G33,2),"") -> 0
A34: Serveur rack standard 1U mono-socket AMD | B34: HPE DL325 Gen10+ CTO Svr | C34: P18606-B21 | D34: 1 | H34: =IF(ISNUMBER(F34),ROUND(F34-G34,2),"")
A35: Processeur 64 bits AMD EPYC 7232P (3,1 GHz de base / 3,2 Ghz Boost / 8 cœurs / 16 threads / 32 Mo cache L3 / 120 W PDT) | B35: HPE DL325 Gen10+ AMD EPYC 7232P FIO Kit | C35: P19634-L21 | D35: 1 | H35: =IF(ISNUMBER(F35),ROUND(F35-G35,2),"")
A36: 1 barrette mémoire HPE DDR4 2933 MHz RDIMM de 32 Go (soit 4 Go ECC par cœur) | B36: HPE 32GB 2Rx4 PC4-3200AA-R Smart Kit | C36: P07646-B21 | D36: 1 | H36: =IF(ISNUMBER(F36),ROUND(F36-G36,2),"")
A37: 1 cage Disque LFF | B37: HPE DL325 Gen10+ 4LFF LP FIO Cage Kit | C37: P15525-B21 | D37: 1 | H37: =IF(ISNUMBER(F37),ROUND(F37-G37,2),"")
A38: 2 ports Ethernet Gigabit intégrés | B38: Marvell QL41132HQRJ Ethernet 10Gb 2-port BASE-T OCP3 Adapter for HPE | C38: P10103-B21 | D38: 1 | H38: =IF(ISNUMBER(F38),ROUND(F38-G38,2),"")
A39: alimentation HPE FlexSlot de 800W certifiée 80PLUS Titanium | B39: HPE 800W FS Ti Ht Plg LH Pwr Sply Kit | C39: 865438-B21 | D39: 1 | H39: =IF(ISNUMBER(F39),ROUND(F39-G39,2),"")
A40: Carte d'administration HPE iLO avec API RESTful compatible IPMI v2.0 et Redfish. Licence en version Advanced avec toutes les options activées | B40: HPE iLO Adv 1-svr Lic 1yr Support | C40: 512485-B21 | D40: 1 | H40: =IF(ISNUMBER(F40),ROUND(F40-G40,2),"")
A41: 1 kit de câbles pour SATA LFF | B41: HPE DL325 Gen10 Plus LFF SATA FIO Cable Kit | C41: P15903-B21 | D41: 1 | H41: =IF(ISNUMBER(F41),ROUND(F41-G41,2),"")
A42: 1 kit de rail pour rack | B42: HPE DL325 Gen10 Plus 1075mm Easy Install Rail Kit | C42: P18544-B21 | D42: 1 | H42: =IF(ISNUMBER(F42),ROUND(F42-G42,2),"")
A43: Suppresion du cable electrique par defaut | B43: HPE Remove Standard Power Cords | C43: 469774-409 | D43: 1 | H43: =IF(ISNUMBER(F43),ROUND(F43-G43,2),"")
A44: Livraison devant la porte | B44: Livraison devant la porte | C44: AC114A | D44: 1 | H44: =IF(ISNUMBER(F44),ROUND(F44-G44,2),"")
...

Sheet Lot 4 - BPU Location
H1: COEFFICIENTS LOCATIF
H2: ='Loc Coefficients Crédit-Bail'!D2 -> 0.26392451 | I2: ='Loc Coefficients Crédit-Bail'!E2 -> 0.13385372 | J2: ='Loc Coefficients Crédit-Bail'!F2 -> 0.091350624 | K2: ='Loc Coefficients Crédit-Bail'!G2 -> 0.070256845
H3: CREDIT-BAIL | L3: LOCATION
A4: Bordereau de prix unitaires | H4: 1 an | I4: 2 ans | J4: 3 ans | K4: 4 ans | L4: 1 an | N4: 2 ans | P4: 3 ans | R4: 4 ans
H5: 4 Trimestres | I5: 8 Trimestres | J5: 12 Trimestres | K5: 16 Trimestres | L5: 4 trimestres | N5: 8 trimestres | P5: 12 trimestres | R5: 16 trimestres
A6: DésignationDescription des matériels | B6: Référence constructeur (le cas échéant) | C6: HPE SKU | D6: Quantités | E6: Column1 | F6: TARIFS en €HT | G6: Références de Location | H6: Loyer Trimestriel €HT | I6: Loyer Trimestriel €HT | J6: Loyer Trimestriel €HT | K6: Loyer Trimestriel €HT | L6: Coefficient Locatif | M6: Loyer Trimestriel €HT | N6: Coefficient Locatif | O6: Loyer Trimestriel €HT | P6: Coefficient Locatif | Q6: Loyer Trimestriel €HT | R6: Coefficient Locatif | S6: Loyer Trimestriel €HT
A7: CATEGORIE 1 : Serveurs Edge ou Standard | H7: =IF(ISNUMBER($F7),ROUND($F7*H$2,2),"") | I7: =IF(ISNUMBER($F7),ROUND($F7*I$2,2),"") | J7: =IF(ISNUMBER($F7),ROUND($F7*J$2,2),"") | K7: =IF(ISNUMBER($F7),ROUND($F7*K$2,2),"") | L7: =IF(ISNUMBER(F7),IF(LEFT(A7,3)="Cat",VLOOKUP(A7,'Loc Configurations Seules'!R:U,4,FALSE),VLOOKUP(G7,'Loc Coefficients Location'!A:D,4,FALSE)),"") | M7: =IF(ISNUMBER(L7),L7*$F7,"") | N7: =IF(ISNUMBER(F7),IF(LEFT(A7,3)="Cat",VLOOKUP(A7,'Loc Configurations Seules'!R:V,5,FALSE),VLOOKUP(G7,'Loc Coefficients Location'!A:E,5,FALSE)),"") | O7: =IF(ISNUMBER(N7),N7*$F7,"") | P7: =IF(ISNUMBER(F7),IF(LEFT(A7,3)="Cat",VLOOKUP(A7,'Loc Configurations Seules'!R:W,6,FALSE),VLOOKUP(G7,'Loc Coefficients Location'!A:F,6,FALSE)),"") | Q7: =IF(ISNUMBER(P7),P7*$F7,"") | R7: =IF(ISNUMBER(F7),IF(LEFT(A7,3)="Cat",VLOOKUP(A7,'Loc Configurations Seules'!R:X,7,FALSE),VLOOKUP(G7,'Loc Coefficients Location'!A:G,7,FALSE)),"") | S7: =IF(ISNUMBER(R7),R7*$F7,"")
A8: Désignation/Description des matériels | B8: Référence constructeur (le cas échéant) | C8: Numéro de référence | D8: Quantités | F8: TARIFS en €HT | H8: =IF(ISNUMBER($F8),ROUND($F8*H$2,2),"") | I8: =IF(ISNUMBER($F8),ROUND($F8*I$2,2),"") | J8: =IF(ISNUMBER($F8),ROUND($F8*J$2,2),"") | K8: =IF(ISNUMBER($F8),ROUND($F8*K$2,2),"") | L8: =IF(ISNUMBER(F8),IF(LEFT(A8,3)="Cat",VLOOKUP(A8,'Loc Configurations Seules'!R:U,4,FALSE),VLOOKUP(G8,'Loc Coefficients Location'!A:D,4,FALSE)),"") | M8: =IF(ISNUMBER(L8),L8*$F8,"") | N8: =IF(ISNUMBER(F8),IF(LEFT(A8,3)="Cat",VLOOKUP(A8,'Loc Configurations Seules'!R:V,5,FALSE),VLOOKUP(G8,'Loc Coefficients Location'!A:E,5,FALSE)),"") | O8: =IF(ISNUMBER(N8),N8*$F8,"") | P8: =IF(ISNUMBER(F8),IF(LEFT(A8,3)="Cat",VLOOKUP(A8,'Loc Configurations Seules'!R:W,6,FALSE),VLOOKUP(G8,'Loc Coefficients Location'!A:F,6,FALSE)),"") | Q8: =IF(ISNUMBER(P8),P8*$F8,"") | R8: =IF(ISNUMBER(F8),IF(LEFT(A8,3)="Cat",VLOOKUP(A8,'Loc Configurations Seules'!R:X,7,FALSE),VLOOKUP(G8,'Loc Coefficients Location'!A:G,7,FALSE)),"") | S8: =IF(ISNUMBER(R8),R8*$F8,"")
A9: Cat1 Conf1 Microserver | B9: HPE ProLiant MicroServer Gen10+ | C9: P16005-421 | F9: 488.24 | H9: =IF(ISNUMBER($F9),ROUND($F9*H$2,2),"") -> 128.86 | I9: =IF(ISNUMBER($F9),ROUND($F9*I$2,2),"") -> 65.35 | J9: =IF(ISNUMBER($F9),ROUND($F9*J$2,2),"") -> 44.6 | K9: =IF(ISNUMBER($F9),ROUND($F9*K$2,2),"") -> 34.3 | L9: =IF(ISNUMBER(F9),IF(LEFT(A9,3)="Cat",VLOOKUP(A9,'Loc Configurations Seules'!R:U,4,FALSE),VLOOKUP(G9,'Loc Coefficients Location'!A:D,4,FALSE)),"") -> 0.188 | M9: =IF(ISNUMBER(L9),L9*$F9,"") -> 91.78912 | N9: =IF(ISNUMBER(F9),IF(LEFT(A9,3)="Cat",VLOOKUP(A9,'Loc Configurations Seules'!R:V,5,FALSE),VLOOKUP(G9,'Loc Coefficients Location'!A:E,5,FALSE)),"") -> 0.0997 | O9: =IF(ISNUMBER(N9),N9*$F9,"") -> 48.677528 | P9: =IF(ISNUMBER(F9),IF(LEFT(A9,3)="Cat",VLOOKUP(A9,'Loc Configurations Seules'!R:W,6,FALSE),VLOOKUP(G9,'Loc Coefficients Location'!A:F,6,FALSE)),"") -> 0.0757 | Q9: =IF(ISNUMBER(P9),P9*$F9,"") -> 36.959768 | R9: =IF(ISNUMBER(F9),IF(LEFT(A9,3)="Cat",VLOOKUP(A9,'Loc Configurations Seules'!R:X,7,FALSE),VLOOKUP(G9,'Loc Coefficients Location'!A:G,7,FALSE)),"") -> 0.0634 | S9: =IF(ISNUMBER(R9),R9*$F9,"") -> 30.954416
A10: Serveur tour Ultra Micro mono-socket | B10: HPE ProLiant MicroServer Gen10 Plus G5420 2-core 1P 8GB-U S100i 4LFF-NHP 180W External PS Server | C10: P16005-421 | D10: 1 | G10: PC_SE/PLX86 | H10: =IF(ISNUMBER($F10),ROUND($F10*H$2,2),"") | I10: =IF(ISNUMBER($F10),ROUND($F10*I$2,2),"") | J10: =IF(ISNUMBER($F10),ROUND($F10*J$2,2),"") | K10: =IF(ISNUMBER($F10),ROUND($F10*K$2,2),"") | L10: =IF(ISNUMBER(F10),IF(LEFT(A10,3)="Cat",VLOOKUP(A10,'Loc Configurations Seules'!R:U,4,FALSE),VLOOKUP(G10,'Loc Coefficients Location'!A:D,4,FALSE)),"") | M10: =IF(ISNUMBER(L10),L10*$F10,"") | N10: =IF(ISNUMBER(F10),IF(LEFT(A10,3)="Cat",VLOOKUP(A10,'Loc Configurations Seules'!R:V,5,FALSE),VLOOKUP(G10,'Loc Coefficients Location'!A:E,5,FALSE)),"") | O10: =IF(ISNUMBER(N10),N10*$F10,"") | P10: =IF(ISNUMBER(F10),IF(LEFT(A10,3)="Cat",VLOOKUP(A10,'Loc Configurations Seules'!R:W,6,FALSE),VLOOKUP(G10,'Loc Coefficients Location'!A:F,6,FALSE)),"") | Q10: =IF(ISNUMBER(P10),P10*$F10,"") | R10: =IF(ISNUMBER(F10),IF(LEFT(A10,3)="Cat",VLOOKUP(A10,'Loc Configurations Seules'!R:X,7,FALSE),VLOOKUP(G10,'Loc Coefficients Location'!A:G,7,FALSE)),"") | S10: =IF(ISNUMBER(R10),R10*$F10,"")
A11: 1 disque de 1 To 6G SATA 7.2K 3,5 pouces (LFF) Non Hot Plug | B11: HPE 1TB SATA 6G Entry 7.2K LFF (3.5in) RW 1yr Wty HDD | C11: 843266-B21 | D11: 1 | G11: Store/PRIMERA | H11: =IF(ISNUMBER($F11),ROUND($F11*H$2,2),"") | I11: =IF(ISNUMBER($F11),ROUND($F11*I$2,2),"") | J11: =IF(ISNUMBER($F11),ROUND($F11*J$2,2),"") | K11: =IF(ISNUMBER($F11),ROUND($F11*K$2,2),"") | L11: =IF(ISNUMBER(F11),IF(LEFT(A11,3)="Cat",VLOOKUP(A11,'Loc Configurations Seules'!R:U,4,FALSE),VLOOKUP(G11,'Loc Coefficients Location'!A:D,4,FALSE)),"") | M11: =IF(ISNUMBER(L11),L11*$F11,"") | N11: =IF(ISNUMBER(F11),IF(LEFT(A11,3)="Cat",VLOOKUP(A11,'Loc Configurations Seules'!R:V,5,FALSE),VLOOKUP(G11,'Loc Coefficients Location'!A:E,5,FALSE)),"") | O11: =IF(ISNUMBER(N11),N11*$F11,"") | P11: =IF(ISNUMBER(F11),IF(LEFT(A11,3)="Cat",VLOOKUP(A11,'Loc Configurations Seules'!R:W,6,FALSE),VLOOKUP(G11,'Loc Coefficients Location'!A:F,6,FALSE)),"") | Q11: =IF(ISNUMBER(P11),P11*$F11,"") | R11: =IF(ISNUMBER(F11),IF(LEFT(A11,3)="Cat",VLOOKUP(A11,'Loc Configurations Seules'!R:X,7,FALSE),VLOOKUP(G11,'Loc Coefficients Location'!A:G,7,FALSE)),"") | S11: =IF(ISNUMBER(R11),R11*$F11,"")
A12: Kit pour carte d'administration HPE iLO | B12: HPE MicroServer Gen10 Plus iLO Enablement Kit | C12: P13788-B21 | D12: 1 | G12: SOFT/MAINT | H12: =IF(ISNUMBER($F12),ROUND($F12*H$2,2),"") | I12: =IF(ISNUMBER($F12),ROUND($F12*I$2,2),"") | J12: =IF(ISNUMBER($F12),ROUND($F12*J$2,2),"") | K12: =IF(ISNUMBER($F12),ROUND($F12*K$2,2),"") | L12: =IF(ISNUMBER(F12),IF(LEFT(A12,3)="Cat",VLOOKUP(A12,'Loc Configurations Seules'!R:U,4,FALSE),VLOOKUP(G12,'Loc Coefficients Location'!A:D,4,FALSE)),"") | M12: =IF(ISNUMBER(L12),L12*$F12,"") | N12: =IF(ISNUMBER(F12),IF(LEFT(A12,3)="Cat",VLOOKUP(A12,'Loc Configurations Seules'!R:V,5,FALSE),VLOOKUP(G12,'Loc Coefficients Location'!A:E,5,FALSE)),"") | O12: =IF(ISNUMBER(N12),N12*$F12,"") | P12: =IF(ISNUMBER(F12),IF(LEFT(A12,3)="Cat",VLOOKUP(A12,'Loc Configurations Seules'!R:W,6,FALSE),VLOOKUP(G12,'Loc Coefficients Location'!A:F,6,FALSE)),"") | Q12: =IF(ISNUMBER(P12),P12*$F12,"") | R12: =IF(ISNUMBER(F12),IF(LEFT(A12,3)="Cat",VLOOKUP(A12,'Loc Configurations Seules'!R:X,7,FALSE),VLOOKUP(G12,'Loc Coefficients Location'!A:G,7,FALSE)),"") | S12: =IF(ISNUMBER(R12),R12*$F12,"")
A13: Carte d'administration HPE iLO avec API RESTful compatible IPMI v2.0 et Redfish. Licence en version Advanced avec toutes les options activées | B13: HPE iLO Advanced 1-server License with 1yr Support on iLO Licensed Features | C13: 512485-B21 | D13: 1 | G13: PC_SE/PLX86 | H13: =IF(ISNUMBER($F13),ROUND($F13*H$2,2),"") | I13: =IF(ISNUMBER($F13),ROUND($F13*I$2,2),"") | J13: =IF(ISNUMBER($F13),ROUND($F13*J$2,2),"") | K13: =IF(ISNUMBER($F13),ROUND($F13*K$2,2),"") | L13: =IF(ISNUMBER(F13),IF(LEFT(A13,3)="Cat",VLOOKUP(A13,'Loc Configurations Seules'!R:U,4,FALSE),VLOOKUP(G13,'Loc Coefficients Location'!A:D,4,FALSE)),"") | M13: =IF(ISNUMBER(L13),L13*$F13,"") | N13: =IF(ISNUMBER(F13),IF(LEFT(A13,3)="Cat",VLOOKUP(A13,'Loc Configurations Seules'!R:V,5,FALSE),VLOOKUP(G13,'Loc Coefficients Location'!A:E,5,FALSE)),"") | O13: =IF(ISNUMBER(N13),N13*$F13,"") | P13: =IF(ISNUMBER(F13),IF(LEFT(A13,3)="Cat",VLOOKUP(A13,'Loc Configurations Seules'!R:W,6,FALSE),VLOOKUP(G13,'Loc Coefficients Location'!A:F,6,FALSE)),"") | Q13: =IF(ISNUMBER(P13),P13*$F13,"") | R13: =IF(ISNUMBER(F13),IF(LEFT(A13,3)="Cat",VLOOKUP(A13,'Loc Configurations Seules'!R:X,7,FALSE),VLOOKUP(G13,'Loc Coefficients Location'!A:G,7,FALSE)),"") | S13: =IF(ISNUMBER(R13),R13*$F13,"")
A14: Livraison devant la porte | B14: Livraison devant la porte | C14: AC114A | D14: 1 | G14: SOFT/MAINT | H14: =IF(ISNUMBER($F14),ROUND($F14*H$2,2),"") | I14: =IF(ISNUMBER($F14),ROUND($F14*I$2,2),"") | J14: =IF(ISNUMBER($F14),ROUND($F14*J$2,2),"") | K14: =IF(ISNUMBER($F14),ROUND($F14*K$2,2),"") | L14: =IF(ISNUMBER(F14),IF(LEFT(A14,3)="Cat",VLOOKUP(A14,'Loc Configurations Seules'!R:U,4,FALSE),VLOOKUP(G14,'Loc Coefficients Location'!A:D,4,FALSE)),"") | M14: =IF(ISNUMBER(L14),L14*$F14,"") | N14: =IF(ISNUMBER(F14),IF(LEFT(A14,3)="Cat",VLOOKUP(A14,'Loc Configurations Seules'!R:V,5,FALSE),VLOOKUP(G14,'Loc Coefficients Location'!A:E,5,FALSE)),"") | O14: =IF(ISNUMBER(N14),N14*$F14,"") | P14: =IF(ISNUMBER(F14),IF(LEFT(A14,3)="Cat",VLOOKUP(A14,'Loc Configurations Seules'!R:W,6,FALSE),VLOOKUP(G14,'Loc Coefficients Location'!A:F,6,FALSE)),"") | Q14: =IF(ISNUMBER(P14),P14*$F14,"") | R14: =IF(ISNUMBER(F14),IF(LEFT(A14,3)="Cat",VLOOKUP(A14,'Loc Configurations Seules'!R:X,7,FALSE),VLOOKUP(G14,'Loc Coefficients Location'!A:G,7,FALSE)),"") | S14: =IF(ISNUMBER(R14),R14*$F14,"")
A15: Garantie 5 ans J+1 | B15: HPE 5Y Tech Care Basic Service | C15: HU4B2A5 | D15: 1 | G15: SOFT/MAINT | H15: =IF(ISNUMBER($F15),ROUND($F15*H$2,2),"") | I15: =IF(ISNUMBER($F15),ROUND($F15*I$2,2),"") | J15: =IF(ISNUMBER($F15),ROUND($F15*J$2,2),"") | K15: =IF(ISNUMBER($F15),ROUND($F15*K$2,2),"")
A16: Garantie 5 ans J+1 ILO | B16: HPE iLO AdvPack NonBL Support | C16: HU4B2A5#7X4 | D16: 1 | G16: SOFT/MAINT | H16: =IF(ISNUMBER($F16),ROUND($F16*H$2,2),"") | I16: =IF(ISNUMBER($F16),ROUND($F16*I$2,2),"") | J16: =IF(ISNUMBER($F16),ROUND($F16*J$2,2),"") | K16: =IF(ISNUMBER($F16),ROUND($F16*K$2,2),"")
A17: Garantie 5 ans J+1 châssis | B17: HPE Microserver Gen10 Plus Support | C17: HU4B2A5#YKX | D17: 1 | G17: SOFT/MAINT | H17: =IF(ISNUMBER($F17),ROUND($F17*H$2,2),"") | I17: =IF(ISNUMBER($F17),ROUND($F17*I$2,2),"") | J17: =IF(ISNUMBER($F17),ROUND($F17*J$2,2),"") | K17: =IF(ISNUMBER($F17),ROUND($F17*K$2,2),"")
H18: =IF(ISNUMBER($F18),ROUND($F18*H$2,2),"") | I18: =IF(ISNUMBER($F18),ROUND($F18*I$2,2),"") | J18: =IF(ISNUMBER($F18),ROUND($F18*J$2,2),"") | K18: =IF(ISNUMBER($F18),ROUND($F18*K$2,2),"") | L18: =IF(ISNUMBER(F18),IF(LEFT(A18,3)="Cat",VLOOKUP(A18,'Loc Configurations Seules'!R:U,4,FALSE),VLOOKUP(G18,'Loc Coefficients Location'!A:D,4,FALSE)),"") | M18: =IF(ISNUMBER(L18),L18*$F18,"") | N18: =IF(ISNUMBER(F18),IF(LEFT(A18,3)="Cat",VLOOKUP(A18,'Loc Configurations Seules'!R:V,5,FALSE),VLOOKUP(G18,'Loc Coefficients Location'!A:E,5,FALSE)),"") | O18: =IF(ISNUMBER(N18),N18*$F18,"") | P18: =IF(ISNUMBER(F18),IF(LEFT(A18,3)="Cat",VLOOKUP(A18,'Loc Configurations Seules'!R:W,6,FALSE),VLOOKUP(G18,'Loc Coefficients Location'!A:F,6,FALSE)),"") | Q18: =IF(ISNUMBER(P18),P18*$F18,"") | R18: =IF(ISNUMBER(F18),IF(LEFT(A18,3)="Cat",VLOOKUP(A18,'Loc Configurations Seules'!R:X,7,FALSE),VLOOKUP(G18,'Loc Coefficients Location'!A:G,7,FALSE)),"") | S18: =IF(ISNUMBER(R18),R18*$F18,"")
A19: Cat1 Conf5 DL20 Gen10 plus | B19: HPE ProLiant DL20 Gen10+ | C19: P44109-B21 | F19: 302.89 | H19: =IF(ISNUMBER($F19),ROUND($F19*H$2,2),"") -> 79.94 | I19: =IF(ISNUMBER($F19),ROUND($F19*I$2,2),"") -> 40.54 | J19: =IF(ISNUMBER($F19),ROUND($F19*J$2,2),"") -> 27.67 | K19: =IF(ISNUMBER($F19),ROUND($F19*K$2,2),"") -> 21.28 | L19: =IF(ISNUMBER(F19),IF(LEFT(A19,3)="Cat",VLOOKUP(A19,'Loc Configurations Seules'!R:U,4,FALSE),VLOOKUP(G19,'Loc Coefficients Location'!A:D,4,FALSE)),"") -> 0.2129 | M19: =IF(ISNUMBER(L19),L19*$F19,"") -> 64.485281 | N19: =IF(ISNUMBER(F19),IF(LEFT(A19,3)="Cat",VLOOKUP(A19,'Loc Configurations Seules'!R:V,5,FALSE),VLOOKUP(G19,'Loc Coefficients Location'!A:E,5,FALSE)),"") -> 0.1109 | O19: =IF(ISNUMBER(N19),N19*$F19,"") -> 33.590501 | P19: =IF(ISNUMBER(F19),IF(LEFT(A19,3)="Cat",VLOOKUP(A19,'Loc Configurations Seules'!R:W,6,FALSE),VLOOKUP(G19,'Loc Coefficients Location'!A:F,6,FALSE)),"") -> 0.0808 | Q19: =IF(ISNUMBER(P19),P19*$F19,"") -> 24.473512 | R19: =IF(ISNUMBER(F19),IF(LEFT(A19,3)="Cat",VLOOKUP(A19,'Loc Configurations Seules'!R:X,7,FALSE),VLOOKUP(G19,'Loc Coefficients Location'!A:G,7,FALSE)),"") -> 0.0657 | S19: =IF(ISNUMBER(R19),R19*$F19,"") -> 19.899873
A20: Serveur rack standard 1U mono-socket INTEL | B20: HPE DL20 Gen10+ 2LFF NHP CTO Svr | C20: P44109-B21 | D20: 1 | G20: PC_SE/PLX86 | H20: =IF(ISNUMBER($F20),ROUND($F20*H$2,2),"") | I20: =IF(ISNUMBER($F20),ROUND($F20*I$2,2),"") | J20: =IF(ISNUMBER($F20),ROUND($F20*J$2,2),"") | K20: =IF(ISNUMBER($F20),ROUND($F20*K$2,2),"") | L20: =IF(ISNUMBER(F20),IF(LEFT(A20,3)="Cat",VLOOKUP(A20,'Loc Configurations Seules'!R:U,4,FALSE),VLOOKUP(G20,'Loc Coefficients Location'!A:D,4,FALSE)),"") | M20: =IF(ISNUMBER(L20),L20*$F20,"") | N20: =IF(ISNUMBER(F20),IF(LEFT(A20,3)="Cat",VLOOKUP(A20,'Loc Configurations Seules'!R:V,5,FALSE),VLOOKUP(G20,'Loc Coefficients Location'!A:E,5,FALSE)),"") | O20: =IF(ISNUMBER(N20),N20*$F20,"") | P20: =IF(ISNUMBER(F20),IF(LEFT(A20,3)="Cat",VLOOKUP(A20,'Loc Configurations Seules'!R:W,6,FALSE),VLOOKUP(G20,'Loc Coefficients Location'!A:F,6,FALSE)),"") | Q20: =IF(ISNUMBER(P20),P20*$F20,"") | R20: =IF(ISNUMBER(F20),IF(LEFT(A20,3)="Cat",VLOOKUP(A20,'Loc Configurations Seules'!R:X,7,FALSE),VLOOKUP(G20,'Loc Coefficients Location'!A:G,7,FALSE)),"") | S20: =IF(ISNUMBER(R20),R20*$F20,"")
A21: Processeur 64 bits Intel Xeon E-2314 (2,8 GHz de base / 4,50 Ghz Turbo / 4 cœurs / 4 threads / 8 Mo Smart Cache / 65 W PDT | B21: Intel Xeon E-2314 2.8GHz 4-core 65W FIO Processor for HPE | C21: P45248-B21 | D21: 1 | G21: PC_SE/PLX86 | H21: =IF(ISNUMBER($F21),ROUND($F21*H$2,2),"") | I21: =IF(ISNUMBER($F21),ROUND($F21*I$2,2),"") | J21: =IF(ISNUMBER($F21),ROUND($F21*J$2,2),"") | K21: =IF(ISNUMBER($F21),ROUND($F21*K$2,2),"") | L21: =IF(ISNUMBER(F21),IF(LEFT(A21,3)="Cat",VLOOKUP(A21,'Loc Configurations Seules'!R:U,4,FALSE),VLOOKUP(G21,'Loc Coefficients Location'!A:D,4,FALSE)),"") | M21: =IF(ISNUMBER(L21),L21*$F21,"") | N21: =IF(ISNUMBER(F21),IF(LEFT(A21,3)="Cat",VLOOKUP(A21,'Loc Configurations Seules'!R:V,5,FALSE),VLOOKUP(G21,'Loc Coefficients Location'!A:E,5,FALSE)),"") | O21: =IF(ISNUMBER(N21),N21*$F21,"") | P21: =IF(ISNUMBER(F21),IF(LEFT(A21,3)="Cat",VLOOKUP(A21,'Loc Configurations Seules'!R:W,6,FALSE),VLOOKUP(G21,'Loc Coefficients Location'!A:F,6,FALSE)),"") | Q21: =IF(ISNUMBER(P21),P21*$F21,"") | R21: =IF(ISNUMBER(F21),IF(LEFT(A21,3)="Cat",VLOOKUP(A21,'Loc Configurations Seules'!R:X,7,FALSE),VLOOKUP(G21,'Loc Coefficients Location'!A:G,7,FALSE)),"") | S21: =IF(ISNUMBER(R21),R21*$F21,"")
A22: 1 barrette mémoire HPE Standard DDR4 2666 MHz UDIMM de 16 Go (soit 4 Go ECC par cœur) | B22: HPE 16GB (1x16GB) Single Rank x8 DDR4-3200 CAS-22-22-22 Unbuffered Standard Memory Kit | C22: P43019-B21 | D22: 1 | G22: PC_SE/PLX86 | H22: =IF(ISNUMBER($F22),ROUND($F22*H$2,2),"") | I22: =IF(ISNUMBER($F22),ROUND($F22*I$2,2),"") | J22: =IF(ISNUMBER($F22),ROUND($F22*J$2,2),"") | K22: =IF(ISNUMBER($F22),ROUND($F22*K$2,2),"") | L22: =IF(ISNUMBER(F22),IF(LEFT(A22,3)="Cat",VLOOKUP(A22,'Loc Configurations Seules'!R:U,4,FALSE),VLOOKUP(G22,'Loc Coefficients Location'!A:D,4,FALSE)),"") | M22: =IF(ISNUMBER(L22),L22*$F22,"") | N22: =IF(ISNUMBER(F22),IF(LEFT(A22,3)="Cat",VLOOKUP(A22,'Loc Configurations Seules'!R:V,5,FALSE),VLOOKUP(G22,'Loc Coefficients Location'!A:E,5,FALSE)),"") | O22: =IF(ISNUMBER(N22),N22*$F22,"") | P22: =IF(ISNUMBER(F22),IF(LEFT(A22,3)="Cat",VLOOKUP(A22,'Loc Configurations Seules'!R:W,6,FALSE),VLOOKUP(G22,'Loc Coefficients Location'!A:F,6,FALSE)),"") | Q22: =IF(ISNUMBER(P22),P22*$F22,"") | R22: =IF(ISNUMBER(F22),IF(LEFT(A22,3)="Cat",VLOOKUP(A22,'Loc Configurations Seules'!R:X,7,FALSE),VLOOKUP(G22,'Loc Coefficients Location'!A:G,7,FALSE)),"") | S22: =IF(ISNUMBER(R22),R22*$F22,"")
A23: 1 cage pour emplacement PCI | B23: HPE ProLiant DL20 Gen10 Plus x8/x8 LP FIO Riser Kit | C23: P46114-B21 | D23: 1 | G23: PC_SE/PLX86 | H23: =IF(ISNUMBER($F23),ROUND($F23*H$2,2),"") | I23: =IF(ISNUMBER($F23),ROUND($F23*I$2,2),"") | J23: =IF(ISNUMBER($F23),ROUND($F23*J$2,2),"") | K23: =IF(ISNUMBER($F23),ROUND($F23*K$2,2),"") | L23: =IF(ISNUMBER(F23),IF(LEFT(A23,3)="Cat",VLOOKUP(A23,'Loc Configurations Seules'!R:U,4,FALSE),VLOOKUP(G23,'Loc Coefficients Location'!A:D,4,FALSE)),"") | M23: =IF(ISNUMBER(L23),L23*$F23,"") | N23: =IF(ISNUMBER(F23),IF(LEFT(A23,3)="Cat",VLOOKUP(A23,'Loc Configurations Seules'!R:V,5,FALSE),VLOOKUP(G23,'Loc Coefficients Location'!A:E,5,FALSE)),"") | O23: =IF(ISNUMBER(N23),N23*$F23,"") | P23: =IF(ISNUMBER(F23),IF(LEFT(A23,3)="Cat",VLOOKUP(A23,'Loc Configurations Seules'!R:W,6,FALSE),VLOOKUP(G23,'Loc Coefficients Location'!A:F,6,FALSE)),"") | Q23: =IF(ISNUMBER(P23),P23*$F23,"") | R23: =IF(ISNUMBER(F23),IF(LEFT(A23,3)="Cat",VLOOKUP(A23,'Loc Configurations Seules'!R:X,7,FALSE),VLOOKUP(G23,'Loc Coefficients Location'!A:G,7,FALSE)),"") | S23: =IF(ISNUMBER(R23),R23*$F23,"")
A24: Alimentation 290W certifiée 80Plus Platinium | B24: HPE DL20 Gen10 Plat 290W FIO PSU Kit | C24: P21649-B21 | D24: 1 | G24: SOFT/MAINT | H24: =IF(ISNUMBER($F24),ROUND($F24*H$2,2),"") | I24: =IF(ISNUMBER($F24),ROUND($F24*I$2,2),"") | J24: =IF(ISNUMBER($F24),ROUND($F24*J$2,2),"") | K24: =IF(ISNUMBER($F24),ROUND($F24*K$2,2),"") | L24: =IF(ISNUMBER(F24),IF(LEFT(A24,3)="Cat",VLOOKUP(A24,'Loc Configurations Seules'!R:U,4,FALSE),VLOOKUP(G24,'Loc Coefficients Location'!A:D,4,FALSE)),"") | M24: =IF(ISNUMBER(L24),L24*$F24,"") | N24: =IF(ISNUMBER(F24),IF(LEFT(A24,3)="Cat",VLOOKUP(A24,'Loc Configurations Seules'!R:V,5,FALSE),VLOOKUP(G24,'Loc Coefficients Location'!A:E,5,FALSE)),"") | O24: =IF(ISNUMBER(N24),N24*$F24,"") | P24: =IF(ISNUMBER(F24),IF(LEFT(A24,3)="Cat",VLOOKUP(A24,'Loc Configurations Seules'!R:W,6,FALSE),VLOOKUP(G24,'Loc Coefficients Location'!A:F,6,FALSE)),"") | Q24: =IF(ISNUMBER(P24),P24*$F24,"") | R24: =IF(ISNUMBER(F24),IF(LEFT(A24,3)="Cat",VLOOKUP(A24,'Loc Configurations Seules'!R:X,7,FALSE),VLOOKUP(G24,'Loc Coefficients Location'!A:G,7,FALSE)),"") | S24: =IF(ISNUMBER(R24),R24*$F24,"")
A25: Carte d'administration HPE iLO avec API RESTful compatible IPMI v2.0 et Redfish. Licence en version Advanced avec toutes les options activées | B25: HPE iLO Adv 1-svr Lic 1yr Support | C25: 512485-B21 | D25: 1 | G25: PC_SE/PLX86 | H25: =IF(ISNUMBER($F25),ROUND($F25*H$2,2),"") | I25: =IF(ISNUMBER($F25),ROUND($F25*I$2,2),"") | J25: =IF(ISNUMBER($F25),ROUND($F25*J$2,2),"") | K25: =IF(ISNUMBER($F25),ROUND($F25*K$2,2),"") | L25: =IF(ISNUMBER(F25),IF(LEFT(A25,3)="Cat",VLOOKUP(A25,'Loc Configurations Seules'!R:U,4,FALSE),VLOOKUP(G25,'Loc Coefficients Location'!A:D,4,FALSE)),"") | M25: =IF(ISNUMBER(L25),L25*$F25,"") | N25: =IF(ISNUMBER(F25),IF(LEFT(A25,3)="Cat",VLOOKUP(A25,'Loc Configurations Seules'!R:V,5,FALSE),VLOOKUP(G25,'Loc Coefficients Location'!A:E,5,FALSE)),"") | O25: =IF(ISNUMBER(N25),N25*$F25,"") | P25: =IF(ISNUMBER(F25),IF(LEFT(A25,3)="Cat",VLOOKUP(A25,'Loc Configurations Seules'!R:W,6,FALSE),VLOOKUP(G25,'Loc Coefficients Location'!A:F,6,FALSE)),"") | Q25: =IF(ISNUMBER(P25),P25*$F25,"") | R25: =IF(ISNUMBER(F25),IF(LEFT(A25,3)="Cat",VLOOKUP(A25,'Loc Configurations Seules'!R:X,7,FALSE),VLOOKUP(G25,'Loc Coefficients Location'!A:G,7,FALSE)),"") | S25: =IF(ISNUMBER(R25),R25*$F25,"")
A26: Suppresion du cable electrique par defaut | B26: HPE Remove Standard Power Cords | C26: 469774-409 | D26: 1 | G26: PC_SE/PLX86 | H26: =IF(ISNUMBER($F26),ROUND($F26*H$2,2),"") | I26: =IF(ISNUMBER($F26),ROUND($F26*I$2,2),"") | J26: =IF(ISNUMBER($F26),ROUND($F26*J$2,2),"") | K26: =IF(ISNUMBER($F26),ROUND($F26*K$2,2),"") | L26: =IF(ISNUMBER(F26),IF(LEFT(A26,3)="Cat",VLOOKUP(A26,'Loc Configurations Seules'!R:U,4,FALSE),VLOOKUP(G26,'Loc Coefficients Location'!A:D,4,FALSE)),"") | M26: =IF(ISNUMBER(L26),L26*$F26,"") | N26: =IF(ISNUMBER(F26),IF(LEFT(A26,3)="Cat",VLOOKUP(A26,'Loc Configurations Seules'!R:V,5,FALSE),VLOOKUP(G26,'Loc Coefficients Location'!A:E,5,FALSE)),"") | O26: =IF(ISNUMBER(N26),N26*$F26,"") | P26: =IF(ISNUMBER(F26),IF(LEFT(A26,3)="Cat",VLOOKUP(A26,'Loc Configurations Seules'!R:W,6,FALSE),VLOOKUP(G26,'Loc Coefficients Location'!A:F,6,FALSE)),"") | Q26: =IF(ISNUMBER(P26),P26*$F26,"") | R26: =IF(ISNUMBER(F26),IF(LEFT(A26,3)="Cat",VLOOKUP(A26,'Loc Configurations Seules'!R:X,7,FALSE),VLOOKUP(G26,'Loc Coefficients Location'!A:G,7,FALSE)),"") | S26: =IF(ISNUMBER(R26),R26*$F26,"")
A27: 1 kit de rail pour rack | B27: HPE 1U Short Friction Rail Kit | C27: 775612-B21 | D27: 1 | G27: SOFT/MAINT | H27: =IF(ISNUMBER($F27),ROUND($F27*H$2,2),"") | I27: =IF(ISNUMBER($F27),ROUND($F27*I$2,2),"") | J27: =IF(ISNUMBER($F27),ROUND($F27*J$2,2),"") | K27: =IF(ISNUMBER($F27),ROUND($F27*K$2,2),"") | L27: =IF(ISNUMBER(F27),IF(LEFT(A27,3)="Cat",VLOOKUP(A27,'Loc Configurations Seules'!R:U,4,FALSE),VLOOKUP(G27,'Loc Coefficients Location'!A:D,4,FALSE)),"") | M27: =IF(ISNUMBER(L27),L27*$F27,"") | N27: =IF(ISNUMBER(F27),IF(LEFT(A27,3)="Cat",VLOOKUP(A27,'Loc Configurations Seules'!R:V,5,FALSE),VLOOKUP(G27,'Loc Coefficients Location'!A:E,5,FALSE)),"") | O27: =IF(ISNUMBER(N27),N27*$F27,"") | P27: =IF(ISNUMBER(F27),IF(LEFT(A27,3)="Cat",VLOOKUP(A27,'Loc Configurations Seules'!R:W,6,FALSE),VLOOKUP(G27,'Loc Coefficients Location'!A:F,6,FALSE)),"") | Q27: =IF(ISNUMBER(P27),P27*$F27,"") | R27: =IF(ISNUMBER(F27),IF(LEFT(A27,3)="Cat",VLOOKUP(A27,'Loc Configurations Seules'!R:X,7,FALSE),VLOOKUP(G27,'Loc Coefficients Location'!A:G,7,FALSE)),"") | S27: =IF(ISNUMBER(R27),R27*$F27,"")
A28: Livraison devant la porte | B28: Livraison devant la porte | C28: AC111A | D28: 1 | G28: SOFT/MAINT | H28: =IF(ISNUMBER($F28),ROUND($F28*H$2,2),"") | I28: =IF(ISNUMBER($F28),ROUND($F28*I$2,2),"") | J28: =IF(ISNUMBER($F28),ROUND($F28*J$2,2),"") | K28: =IF(ISNUMBER($F28),ROUND($F28*K$2,2),"") | L28: =IF(ISNUMBER(F28),IF(LEFT(A28,3)="Cat",VLOOKUP(A28,'Loc Configurations Seules'!R:U,4,FALSE),VLOOKUP(G28,'Loc Coefficients Location'!A:D,4,FALSE)),"") | M28: =IF(ISNUMBER(L28),L28*$F28,"") | N28: =IF(ISNUMBER(F28),IF(LEFT(A28,3)="Cat",VLOOKUP(A28,'Loc Configurations Seules'!R:V,5,FALSE),VLOOKUP(G28,'Loc Coefficients Location'!A:E,5,FALSE)),"") | O28: =IF(ISNUMBER(N28),N28*$F28,"") | P28: =IF(ISNUMBER(F28),IF(LEFT(A28,3)="Cat",VLOOKUP(A28,'Loc Configurations Seules'!R:W,6,FALSE),VLOOKUP(G28,'Loc Coefficients Location'!A:F,6,FALSE)),"") | Q28: =IF(ISNUMBER(P28),P28*$F28,"") | R28: =IF(ISNUMBER(F28),IF(LEFT(A28,3)="Cat",VLOOKUP(A28,'Loc Configurations Seules'!R:X,7,FALSE),VLOOKUP(G28,'Loc Coefficients Location'!A:G,7,FALSE)),"") | S28: =IF(ISNUMBER(R28),R28*$F28,"")
A29: Garantie 5 ans J+1 | B29: HPE 5Y Tech Care Basic Service | C29: HU4B2A5 | D29: 1 | G29: SOFT/MAINT | H29: =IF(ISNUMBER($F29),ROUND($F29*H$2,2),"") | I29: =IF(ISNUMBER($F29),ROUND($F29*I$2,2),"") | J29: =IF(ISNUMBER($F29),ROUND($F29*J$2,2),"") | K29: =IF(ISNUMBER($F29),ROUND($F29*K$2,2),"")
A30: Garantie 5 ans J+1 ILO | B30: HPE iLO AdvPack NonBL Support | C30: HU4B2A5#7X4 | D30: 1 | G30: SOFT/MAINT | H30: =IF(ISNUMBER($F30),ROUND($F30*H$2,2),"") | I30: =IF(ISNUMBER($F30),ROUND($F30*I$2,2),"") | J30: =IF(ISNUMBER($F30),ROUND($F30*J$2,2),"") | K30: =IF(ISNUMBER($F30),ROUND($F30*K$2,2),"")
A31: Garantie 5 ans J+1 châssis | B31: HPE ProLiant DL20 Gen10+ Support | C31: HU4B2A5#ZX1 | D31: 1 | G31: SOFT/MAINT | H31: =IF(ISNUMBER($F31),ROUND($F31*H$2,2),"") | I31: =IF(ISNUMBER($F31),ROUND($F31*I$2,2),"") | J31: =IF(ISNUMBER($F31),ROUND($F31*J$2,2),"") | K31: =IF(ISNUMBER($F31),ROUND($F31*K$2,2),"")
H32: =IF(ISNUMBER($F32),ROUND($F32*H$2,2),"") | I32: =IF(ISNUMBER($F32),ROUND($F32*I$2,2),"") | J32: =IF(ISNUMBER($F32),ROUND($F32*J$2,2),"") | K32: =IF(ISNUMBER($F32),ROUND($F32*K$2,2),"") | L32: =IF(ISNUMBER(F32),IF(LEFT(A32,3)="Cat",VLOOKUP(A32,'Loc Configurations Seules'!R:U,4,FALSE),VLOOKUP(G32,'Loc Coefficients Location'!A:D,4,FALSE)),"") | M32: =IF(ISNUMBER(L32),L32*$F32,"") | N32: =IF(ISNUMBER(F32),IF(LEFT(A32,3)="Cat",VLOOKUP(A32,'Loc Configurations Seules'!R:V,5,FALSE),VLOOKUP(G32,'Loc Coefficients Location'!A:E,5,FALSE)),"") | O32: =IF(ISNUMBER(N32),N32*$F32,"") | P32: =IF(ISNUMBER(F32),IF(LEFT(A32,3)="Cat",VLOOKUP(A32,'Loc Configurations Seules'!R:W,6,FALSE),VLOOKUP(G32,'Loc Coefficients Location'!A:F,6,FALSE)),"") | Q32: =IF(ISNUMBER(P32),P32*$F32,"") | R32: =IF(ISNUMBER(F32),IF(LEFT(A32,3)="Cat",VLOOKUP(A32,'Loc Configurations Seules'!R:X,7,FALSE),VLOOKUP(G32,'Loc Coefficients Location'!A:G,7,FALSE)),"") | S32: =IF(ISNUMBER(R32),R32*$F32,"")
A33: Cat1 Conf2 DL325 Gen10 plus | B33: HPE ProLiant DL325 Gen10+ | C33: P18606-B21 | F33: 674.1 | H33: =IF(ISNUMBER($F33),ROUND($F33*H$2,2),"") -> 177.91 | I33: =IF(ISNUMBER($F33),ROUND($F33*I$2,2),"") -> 90.23 | J33: =IF(ISNUMBER($F33),ROUND($F33*J$2,2),"") -> 61.58 | K33: =IF(ISNUMBER($F33),ROUND($F33*K$2,2),"") -> 47.36 | L33: =IF(ISNUMBER(F33),IF(LEFT(A33,3)="Cat",VLOOKUP(A33,'Loc Configurations Seules'!R:U,4,FALSE),VLOOKUP(G33,'Loc Coefficients Location'!A:D,4,FALSE)),"") -> 0.2046 | M33: =IF(ISNUMBER(L33),L33*$F33,"") -> 137.92086 | N33: =IF(ISNUMBER(F33),IF(LEFT(A33,3)="Cat",VLOOKUP(A33,'Loc Configurations Seules'!R:V,5,FALSE),VLOOKUP(G33,'Loc Coefficients Location'!A:E,5,FALSE)),"") -> 0.1072 | O33: =IF(ISNUMBER(N33),N33*$F33,"") -> 72.26352 | P33: =IF(ISNUMBER(F33),IF(LEFT(A33,3)="Cat",VLOOKUP(A33,'Loc Configurations Seules'!R:W,6,FALSE),VLOOKUP(G33,'Loc Coefficients Location'!A:F,6,FALSE)),"") -> 0.0791 | Q33: =IF(ISNUMBER(P33),P33*$F33,"") -> 53.32131 | R33: =IF(ISNUMBER(F33),IF(LEFT(A33,3)="Cat",VLOOKUP(A33,'Loc Configurations Seules'!R:X,7,FALSE),VLOOKUP(G33,'Loc Coefficients Location'!A:G,7,FALSE)),"") -> 0.0649 | S33: =IF(ISNUMBER(R33),R33*$F33,"") -> 43.74909
A34: Serveur rack standard 1U mono-socket AMD | B34: HPE DL325 Gen10+ CTO Svr | C34: P18606-B21 | D34: 1 | G34: PC_SE/PLX86 | H34: =IF(ISNUMBER($F34),ROUND($F34*H$2,2),"") | I34: =IF(ISNUMBER($F34),ROUND($F34*I$2,2),"") | J34: =IF(ISNUMBER($F34),ROUND($F34*J$2,2),"") | K34: =IF(ISNUMBER($F34),ROUND($F34*K$2,2),"") | L34: =IF(ISNUMBER(F34),IF(LEFT(A34,3)="Cat",VLOOKUP(A34,'Loc Configurations Seules'!R:U,4,FALSE),VLOOKUP(G34,'Loc Coefficients Location'!A:D,4,FALSE)),"") | M34: =IF(ISNUMBER(L34),L34*$F34,"") | N34: =IF(ISNUMBER(F34),IF(LEFT(A34,3)="Cat",VLOOKUP(A34,'Loc Configurations Seules'!R:V,5,FALSE),VLOOKUP(G34,'Loc Coefficients Location'!A:E,5,FALSE)),"") | O34: =IF(ISNUMBER(N34),N34*$F34,"") | P34: =IF(ISNUMBER(F34),IF(LEFT(A34,3)="Cat",VLOOKUP(A34,'Loc Configurations Seules'!R:W,6,FALSE),VLOOKUP(G34,'Loc Coefficients Location'!A:F,6,FALSE)),"") | Q34: =IF(ISNUMBER(P34),P34*$F34,"") | R34: =IF(ISNUMBER(F34),IF(LEFT(A34,3)="Cat",VLOOKUP(A34,'Loc Configurations Seules'!R:X,7,FALSE),VLOOKUP(G34,'Loc Coefficients Location'!A:G,7,FALSE)),"") | S34: =IF(ISNUMBER(R34),R34*$F34,"")
A35: Processeur 64 bits AMD EPYC 7232P (3,1 GHz de base / 3,2 Ghz Boost / 8 cœurs / 16 threads / 32 Mo cache L3 / 120 W PDT) | B35: HPE DL325 Gen10+ AMD EPYC 7232P FIO Kit | C35: P19634-L21 | D35: 1 | G35: PC_SE/PLX86 | H35: =IF(ISNUMBER($F35),ROUND($F35*H$2,2),"") | I35: =IF(ISNUMBER($F35),ROUND($F35*I$2,2),"") | J35: =IF(ISNUMBER($F35),ROUND($F35*J$2,2),"") | K35: =IF(ISNUMBER($F35),ROUND($F35*K$2,2),"") | L35: =IF(ISNUMBER(F35),IF(LEFT(A35,3)="Cat",VLOOKUP(A35,'Loc Configurations Seules'!R:U,4,FALSE),VLOOKUP(G35,'Loc Coefficients Location'!A:D,4,FALSE)),"") | M35: =IF(ISNUMBER(L35),L35*$F35,"") | N35: =IF(ISNUMBER(F35),IF(LEFT(A35,3)="Cat",VLOOKUP(A35,'Loc Configurations Seules'!R:V,5,FALSE),VLOOKUP(G35,'Loc Coefficients Location'!A:E,5,FALSE)),"") | O35: =IF(ISNUMBER(N35),N35*$F35,"") | P35: =IF(ISNUMBER(F35),IF(LEFT(A35,3)="Cat",VLOOKUP(A35,'Loc Configurations Seules'!R:W,6,FALSE),VLOOKUP(G35,'Loc Coefficients Location'!A:F,6,FALSE)),"") | Q35: =IF(ISNUMBER(P35),P35*$F35,"") | R35: =IF(ISNUMBER(F35),IF(LEFT(A35,3)="Cat",VLOOKUP(A35,'Loc Configurations Seules'!R:X,7,FALSE),VLOOKUP(G35,'Loc Coefficients Location'!A:G,7,FALSE)),"") | S35: =IF(ISNUMBER(R35),R35*$F35,"")
A36: 1 barrette mémoire HPE DDR4 2933 MHz RDIMM de 32 Go (soit 4 Go ECC par cœur) | B36: HPE 32GB 2Rx4 PC4-3200AA-R Smart Kit | C36: P07646-B21 | D36: 1 | G36: PC_SE/PLX86 | H36: =IF(ISNUMBER($F36),ROUND($F36*H$2,2),"") | I36: =IF(ISNUMBER($F36),ROUND($F36*I$2,2),"") | J36: =IF(ISNUMBER($F36),ROUND($F36*J$2,2),"") | K36: =IF(ISNUMBER($F36),ROUND($F36*K$2,2),"") | L36: =IF(ISNUMBER(F36),IF(LEFT(A36,3)="Cat",VLOOKUP(A36,'Loc Configurations Seules'!R:U,4,FALSE),VLOOKUP(G36,'Loc Coefficients Location'!A:D,4,FALSE)),"") | M36: =IF(ISNUMBER(L36),L36*$F36,"") | N36: =IF(ISNUMBER(F36),IF(LEFT(A36,3)="Cat",VLOOKUP(A36,'Loc Configurations Seules'!R:V,5,FALSE),VLOOKUP(G36,'Loc Coefficients Location'!A:E,5,FALSE)),"") | O36: =IF(ISNUMBER(N36),N36*$F36,"") | P36: =IF(ISNUMBER(F36),IF(LEFT(A36,3)="Cat",VLOOKUP(A36,'Loc Configurations Seules'!R:W,6,FALSE),VLOOKUP(G36,'Loc Coefficients Location'!A:F,6,FALSE)),"") | Q36: =IF(ISNUMBER(P36),P36*$F36,"") | R36: =IF(ISNUMBER(F36),IF(LEFT(A36,3)="Cat",VLOOKUP(A36,'Loc Configurations Seules'!R:X,7,FALSE),VLOOKUP(G36,'Loc Coefficients Location'!A:G,7,FALSE)),"") | S36: =IF(ISNUMBER(R36),R36*$F36,"")
A37: 1 cage Disque LFF | B37: HPE DL325 Gen10+ 4LFF LP FIO Cage Kit | C37: P15525-B21 | D37: 1 | G37: PC_SE/PLX86 | H37: =IF(ISNUMBER($F37),ROUND($F37*H$2,2),"") | I37: =IF(ISNUMBER($F37),ROUND($F37*I$2,2),"") | J37: =IF(ISNUMBER($F37),ROUND($F37*J$2,2),"") | K37: =IF(ISNUMBER($F37),ROUND($F37*K$2,2),"") | L37: =IF(ISNUMBER(F37),IF(LEFT(A37,3)="Cat",VLOOKUP(A37,'Loc Configurations Seules'!R:U,4,FALSE),VLOOKUP(G37,'Loc Coefficients Location'!A:D,4,FALSE)),"") | M37: =IF(ISNUMBER(L37),L37*$F37,"") | N37: =IF(ISNUMBER(F37),IF(LEFT(A37,3)="Cat",VLOOKUP(A37,'Loc Configurations Seules'!R:V,5,FALSE),VLOOKUP(G37,'Loc Coefficients Location'!A:E,5,FALSE)),"") | O37: =IF(ISNUMBER(N37),N37*$F37,"") | P37: =IF(ISNUMBER(F37),IF(LEFT(A37,3)="Cat",VLOOKUP(A37,'Loc Configurations Seules'!R:W,6,FALSE),VLOOKUP(G37,'Loc Coefficients Location'!A:F,6,FALSE)),"") | Q37: =IF(ISNUMBER(P37),P37*$F37,"") | R37: =IF(ISNUMBER(F37),IF(LEFT(A37,3)="Cat",VLOOKUP(A37,'Loc Configurations Seules'!R:X,7,FALSE),VLOOKUP(G37,'Loc Coefficients Location'!A:G,7,FALSE)),"") | S37: =IF(ISNUMBER(R37),R37*$F37,"")
A38: 2 ports Ethernet Gigabit intégrés | B38: Marvell QL41132HQRJ Ethernet 10Gb 2-port BASE-T OCP3 Adapter for HPE | C38: P10103-B21 | D38: 1 | G38: PC_SE/PLX86 | H38: =IF(ISNUMBER($F38),ROUND($F38*H$2,2),"") | I38: =IF(ISNUMBER($F38),ROUND($F38*I$2,2),"") | J38: =IF(ISNUMBER($F38),ROUND($F38*J$2,2),"") | K38: =IF(ISNUMBER($F38),ROUND($F38*K$2,2),"") | L38: =IF(ISNUMBER(F38),IF(LEFT(A38,3)="Cat",VLOOKUP(A38,'Loc Configurations Seules'!R:U,4,FALSE),VLOOKUP(G38,'Loc Coefficients Location'!A:D,4,FALSE)),"") | M38: =IF(ISNUMBER(L38),L38*$F38,"") | N38: =IF(ISNUMBER(F38),IF(LEFT(A38,3)="Cat",VLOOKUP(A38,'Loc Configurations Seules'!R:V,5,FALSE),VLOOKUP(G38,'Loc Coefficients Location'!A:E,5,FALSE)),"") | O38: =IF(ISNUMBER(N38),N38*$F38,"") | P38: =IF(ISNUMBER(F38),IF(LEFT(A38,3)="Cat",VLOOKUP(A38,'Loc Configurations Seules'!R:W,6,FALSE),VLOOKUP(G38,'Loc Coefficients Location'!A:F,6,FALSE)),"") | Q38: =IF(ISNUMBER(P38),P38*$F38,"") | R38: =IF(ISNUMBER(F38),IF(LEFT(A38,3)="Cat",VLOOKUP(A38,'Loc Configurations Seules'!R:X,7,FALSE),VLOOKUP(G38,'Loc Coefficients Location'!A:G,7,FALSE)),"") | S38: =IF(ISNUMBER(R38),R38*$F38,"")
A39: alimentation HPE FlexSlot de 800W certifiée 80PLUS Titanium | B39: HPE 800W FS Ti Ht Plg LH Pwr Sply Kit | C39: 865438-B21 | D39: 1 | G39: PC_SE/PLX86 | H39: =IF(ISNUMBER($F39),ROUND($F39*H$2,2),"") | I39: =IF(ISNUMBER($F39),ROUND($F39*I$2,2),"") | J39: =IF(ISNUMBER($F39),ROUND($F39*J$2,2),"") | K39: =IF(ISNUMBER($F39),ROUND($F39*K$2,2),"") | L39: =IF(ISNUMBER(F39),IF(LEFT(A39,3)="Cat",VLOOKUP(A39,'Loc Configurations Seules'!R:U,4,FALSE),VLOOKUP(G39,'Loc Coefficients Location'!A:D,4,FALSE)),"") | M39: =IF(ISNUMBER(L39),L39*$F39,"") | N39: =IF(ISNUMBER(F39),IF(LEFT(A39,3)="Cat",VLOOKUP(A39,'Loc Configurations Seules'!R:V,5,FALSE),VLOOKUP(G39,'Loc Coefficients Location'!A:E,5,FALSE)),"") | O39: =IF(ISNUMBER(N39),N39*$F39,"") | P39: =IF(ISNUMBER(F39),IF(LEFT(A39,3)="Cat",VLOOKUP(A39,'Loc Configurations Seules'!R:W,6,FALSE),VLOOKUP(G39,'Loc Coefficients Location'!A:F,6,FALSE)),"") | Q39: =IF(ISNUMBER(P39),P39*$F39,"") | R39: =IF(ISNUMBER(F39),IF(LEFT(A39,3)="Cat",VLOOKUP(A39,'Loc Configurations Seules'!R:X,7,FALSE),VLOOKUP(G39,'Loc Coefficients Location'!A:G,7,FALSE)),"") | S39: =IF(ISNUMBER(R39),R39*$F39,"")
A40: Carte d'administration HPE iLO avec API RESTful compatible IPMI v2.0 et Redfish. Licence en version Advanced avec toutes les options activées | B40: HPE iLO Adv 1-svr Lic 1yr Support | C40: 512485-B21 | D40: 1 | G40: PC_SE/PLX86 | H40: =IF(ISNUMBER($F40),ROUND($F40*H$2,2),"") | I40: =IF(ISNUMBER($F40),ROUND($F40*I$2,2),"") | J40: =IF(ISNUMBER($F40),ROUND($F40*J$2,2),"") | K40: =IF(ISNUMBER($F40),ROUND($F40*K$2,2),"") | L40: =IF(ISNUMBER(F40),IF(LEFT(A40,3)="Cat",VLOOKUP(A40,'Loc Configurations Seules'!R:U,4,FALSE),VLOOKUP(G40,'Loc Coefficients Location'!A:D,4,FALSE)),"") | M40: =IF(ISNUMBER(L40),L40*$F40,"") | N40: =IF(ISNUMBER(F40),IF(LEFT(A40,3)="Cat",VLOOKUP(A40,'Loc Configurations Seules'!R:V,5,FALSE),VLOOKUP(G40,'Loc Coefficients Location'!A:E,5,FALSE)),"") | O40: =IF(ISNUMBER(N40),N40*$F40,"") | P40: =IF(ISNUMBER(F40),IF(LEFT(A40,3)="Cat",VLOOKUP(A40,'Loc Configurations Seules'!R:W,6,FALSE),VLOOKUP(G40,'Loc Coefficients Location'!A:F,6,FALSE)),"") | Q40: =IF(ISNUMBER(P40),P40*$F40,"") | R40: =IF(ISNUMBER(F40),IF(LEFT(A40,3)="Cat",VLOOKUP(A40,'Loc Configurations Seules'!R:X,7,FALSE),VLOOKUP(G40,'Loc Coefficients Location'!A:G,7,FALSE)),"") | S40: =IF(ISNUMBER(R40),R40*$F40,"")
...

Sheet Loc Configurations Seules
F1: COEFFICIENTS LOCATIF
F2: 0.2639 | G2: 0.1339 | H2: 0.0914 | I2: 0.0703
F3: CREDIT-BAIL | J3: LOCATION
F4: 1 an | G4: 2 ans | H4: 3 ans | I4: 4 ans | J4: 1 an | L4: 2 ans | N4: 3 ans | P4: 4 ans | U4: 1 an | V4: 2 ans | W4: 3 ans | X4: 4 ans
F5: 4 Trimestres | G5: 8 Trimestres | H5: 12 Trimestres | I5: 16 Trimestres | J5: 4 trimestres | L5: 8 trimestres | N5: 12 trimestres | P5: 16 trimestres | U5: 4 trimestres | V5: 8 trimestres | W5: 12 trimestres | X5: 16 trimestres
A6: Désignation/Description des matériels | B6: Référence constructeur (le cas échéant) | C6: Numéro de référence | D6: Quantités | E6: TARIFS en €HT | F6: Loyer Trimestriel €HT | J6: Coefficient Locatif | K6: Loyer Trimestriel €HT | L6: Coefficient Locatif | M6: Loyer Trimestriel €HT | N6: Coefficient Locatif | O6: Loyer Trimestriel €HT | P6: Coefficient Locatif | Q6: Loyer Trimestriel €HT | R6: Désignation/Description des matériels | U6: Coefficient Locatif | V6: Coefficient Locatif | W6: Coefficient Locatif | X6: Coefficient Locatif
A7: Cat1 Conf1 Microserver | B7: =VLOOKUP(A7,'Lot 4 - Bordereau de prix'!A:B,2,FALSE) -> HPE ProLiant MicroServer Gen10+ | C7: =VLOOKUP(A7,'Lot 4 - Bordereau de prix'!A:C,3,FALSE) -> P16005-421 | D7: 1 | E7: =VLOOKUP(A7,'Lot 4 - Bordereau de prix'!A:F,6,FALSE) -> 488.24 | F7: =ROUND($E7*F$2,2) -> 128.85 | G7: =ROUND($E7*G$2,2) -> 65.38 | H7: =ROUND($E7*H$2,2) -> 44.63 | I7: =ROUND($E7*I$2,2) -> 34.32 | J7: =U7 -> 0.188 | K7: =$E7*J7 -> 91.78912 | L7: =V7 -> 0.0997 | M7: =$E7*L7 -> 48.677528 | N7: =W7 -> 0.0757 | O7: =$E7*N7 -> 36.959768 | P7: =X7 -> 0.0634 | Q7: =$E7*P7 -> 30.954416 | R7: Cat1 Conf1 Microserver | U7: 0.188 | V7: 0.0997 | W7: 0.0757 | X7: 0.0634
A8: Cat1 Conf5 DL20 Gen10 plus | B8: =VLOOKUP(A8,'Lot 4 - Bordereau de prix'!A:B,2,FALSE) -> HPE ProLiant DL20 Gen10+ | C8: =VLOOKUP(A8,'Lot 4 - Bordereau de prix'!A:C,3,FALSE) -> P44109-B21 | D8: 1 | E8: =VLOOKUP(A8,'Lot 4 - Bordereau de prix'!A:F,6,FALSE) -> 302.89 | F8: =ROUND($E8*F$2,2) -> 79.93 | G8: =ROUND($E8*G$2,2) -> 40.56 | H8: =ROUND($E8*H$2,2) -> 27.68 | I8: =ROUND($E8*I$2,2) -> 21.29 | J8: =U8 -> 0.2129 | K8: =$E8*J8 -> 64.485281 | L8: =V8 -> 0.1109 | M8: =$E8*L8 -> 33.590501 | N8: =W8 -> 0.0808 | O8: =$E8*N8 -> 24.473512 | P8: =X8 -> 0.0657 | Q8: =$E8*P8 -> 19.899873 | R8: Cat1 Conf5 DL20 Gen10 plus | U8: 0.2129 | V8: 0.1109 | W8: 0.0808 | X8: 0.0657
A9: Cat1 Conf2 DL325 Gen10 plus | B9: =VLOOKUP(A9,'Lot 4 - Bordereau de prix'!A:B,2,FALSE) -> HPE ProLiant DL325 Gen10+ | C9: =VLOOKUP(A9,'Lot 4 - Bordereau de prix'!A:C,3,FALSE) -> P18606-B21 | D9: 1 | E9: =VLOOKUP(A9,'Lot 4 - Bordereau de prix'!A:F,6,FALSE) -> 674.1 | F9: =ROUND($E9*F$2,2) -> 177.89 | G9: =ROUND($E9*G$2,2) -> 90.26 | H9: =ROUND($E9*H$2,2) -> 61.61 | I9: =ROUND($E9*I$2,2) -> 47.39 | J9: =U9 -> 0.2046 | K9: =$E9*J9 -> 137.92086 | L9: =V9 -> 0.1072 | M9: =$E9*L9 -> 72.26352 | N9: =W9 -> 0.0791 | O9: =$E9*N9 -> 53.32131 | P9: =X9 -> 0.0649 | Q9: =$E9*P9 -> 43.74909 | R9: Cat1 Conf2 DL325 Gen10 plus | U9: 0.2046 | V9: 0.1072 | W9: 0.0791 | X9: 0.0649
A10: Cat1 Conf3 Edge EL300 | B10: =VLOOKUP(A10,'Lot 4 - Bordereau de prix'!A:B,2,FALSE) -> HPE EL300 v2 | C10: =VLOOKUP(A10,'Lot 4 - Bordereau de prix'!A:C,3,FALSE) -> P25828-B21 | D10: 1 | E10: =VLOOKUP(A10,'Lot 4 - Bordereau de prix'!A:F,6,FALSE) -> 1666.29 | F10: =ROUND($E10*F$2,2) -> 439.73 | G10: =ROUND($E10*G$2,2) -> 223.12 | H10: =ROUND($E10*H$2,2) -> 152.3 | I10: =ROUND($E10*I$2,2) -> 117.14 | J10: =U10 -> 0.2207 | K10: =$E10*J10 -> 367.7502 | L10: =V10 -> 0.1151 | M10: =$E10*L10 -> 191.78998 | N10: =W10 -> 0.082 | O10: =$E10*N10 -> 136.63578 | P10: =X10 -> 0.0662 | Q10: =$E10*P10 -> 110.3084 | R10: Cat1 Conf3 Edge EL300 | U10: 0.2207 | V10: 0.1151 | W10: 0.082 | X10: 0.0662
A11: Cat1 Conf6 Tour ML30 Gen10 plus | B11: =VLOOKUP(A11,'Lot 4 - Bordereau de prix'!A:B,2,FALSE) -> HPE ProLiant ML30 Gen10+ | C11: =VLOOKUP(A11,'Lot 4 - Bordereau de prix'!A:C,3,FALSE) -> P44723-B21 | D11: 1 | E11: =VLOOKUP(A11,'Lot 4 - Bordereau de prix'!A:F,6,FALSE) -> 721.84 | F11: =ROUND($E11*F$2,2) -> 190.49 | G11: =ROUND($E11*G$2,2) -> 96.65 | H11: =ROUND($E11*H$2,2) -> 65.98 | I11: =ROUND($E11*I$2,2) -> 50.75 | J11: =U11 -> 0.2004 | K11: =$E11*J11 -> 144.65674 | L11: =V11 -> 0.1053 | M11: =$E11*L11 -> 76.009752 | N11: =W11 -> 0.0783 | O11: =$E11*N11 -> 56.520072 | P11: =X11 -> 0.0645 | Q11: =$E11*P11 -> 46.55868 | R11: Cat1 Conf6 Tour ML30 Gen10 plus | U11: 0.2004 | V11: 0.1053 | W11: 0.0783 | X11: 0.0645
A12: Cat2 Conf1 DL380 Gen10 | B12: =VLOOKUP(A12,'Lot 4 - Bordereau de prix'!A:B,2,FALSE) -> HPE ProLiant DL380 Gen10 | C12: =VLOOKUP(A12,'Lot 4 - Bordereau de prix'!A:C,3,FALSE) -> 868703-B21 | D12: 1 | E12: =VLOOKUP(A12,'Lot 4 - Bordereau de prix'!A:F,6,FALSE) -> 884.1 | F12: =ROUND($E12*F$2,2) -> 233.31 | G12: =ROUND($E12*G$2,2) -> 118.38 | H12: =ROUND($E12*H$2,2) -> 80.81 | I12: =ROUND($E12*I$2,2) -> 62.15 | J12: =U12 -> 0.2059 | K12: =$E12*J12 -> 182.03619 | L12: =V12 -> 0.1078 | M12: =$E12*L12 -> 95.30598 | N12: =W12 -> 0.0794 | O12: =$E12*N12 -> 70.19754 | P12: =X12 -> 0.065 | Q12: =$E12*P12 -> 57.4665 | R12: Cat2 Conf1 DL380 Gen10 | U12: 0.2059 | V12: 0.1078 | W12: 0.0794 | X12: 0.065
A13: Cat2 Conf5 DL160 Gen10 | B13: =VLOOKUP(A13,'Lot 4 - Bordereau de prix'!A:B,2,FALSE) -> HPE ProLiant DL160 Gen10 | C13: =VLOOKUP(A13,'Lot 4 - Bordereau de prix'!A:C,3,FALSE) -> 878973-B21 | D13: 1 | E13: =VLOOKUP(A13,'Lot 4 - Bordereau de prix'!A:F,6,FALSE) -> 830.54 | F13: =ROUND($E13*F$2,2) -> 219.18 | G13: =ROUND($E13*G$2,2) -> 111.21 | H13: =ROUND($E13*H$2,2) -> 75.91 | I13: =ROUND($E13*I$2,2) -> 58.39 | J13: =U13 -> 0.204 | K13: =$E13*J13 -> 169.43016 | L13: =V13 -> 0.1069 | M13: =$E13*L13 -> 88.784726 | N13: =W13 -> 0.079 | O13: =$E13*N13 -> 65.61266 | P13: =X13 -> 0.0649 | Q13: =$E13*P13 -> 53.902046 | R13: Cat2 Conf5 DL160 Gen10 | U13: 0.204 | V13: 0.1069 | W13: 0.079 | X13: 0.0649
A14: Cat2 Conf2 DL380 Gen10 NC | B14: =VLOOKUP(A14,'Lot 4 - Bordereau de prix'!A:B,2,FALSE) -> HPE ProLiant DL380 Gen10 | C14: =VLOOKUP(A14,'Lot 4 - Bordereau de prix'!A:C,3,FALSE) -> P19720-B21 | D14: 1 | E14: =VLOOKUP(A14,'Lot 4 - Bordereau de prix'!A:F,6,FALSE) -> 988.05 | F14: =ROUND($E14*F$2,2) -> 260.75 | G14: =ROUND($E14*G$2,2) -> 132.3 | H14: =ROUND($E14*H$2,2) -> 90.31 | I14: =ROUND($E14*I$2,2) -> 69.46 | J14: =U14 -> 0.2039 | K14: =$E14*J14 -> 201.46339 | L14: =V14 -> 0.1068 | M14: =$E14*L14 -> 105.52374 | N14: =W14 -> 0.079 | O14: =$E14*N14 -> 78.05595 | P14: =X14 -> 0.0648 | Q14: =$E14*P14 -> 64.02564 | R14: Cat2 Conf2 DL380 Gen10 NC | U14: 0.2039 | V14: 0.1068 | W14: 0.079 | X14: 0.0648
A15: Cat2 Conf6 DL180 Gen10 Intel | B15: =VLOOKUP(A15,'Lot 4 - Bordereau de prix'!A:B,2,FALSE) -> HPE ProLiant DL180 Gen10 | C15: =VLOOKUP(A15,'Lot 4 - Bordereau de prix'!A:C,3,FALSE) -> 879517-B21 | D15: 1 | E15: =VLOOKUP(A15,'Lot 4 - Bordereau de prix'!A:F,6,FALSE) -> 901.94 | F15: =ROUND($E15*F$2,2) -> 238.02 | G15: =ROUND($E15*G$2,2) -> 120.77 | H15: =ROUND($E15*H$2,2) -> 82.44 | I15: =ROUND($E15*I$2,2) -> 63.41 | J15: =U15 -> 0.2055 | K15: =$E15*J15 -> 185.34867 | L15: =V15 -> 0.1076 | M15: =$E15*L15 -> 97.048744 | N15: =W15 -> 0.0793 | O15: =$E15*N15 -> 71.523842 | P15: =X15 -> 0.065 | Q15: =$E15*P15 -> 58.6261 | R15: Cat2 Conf6 DL180 Gen10 Intel | U15: 0.2055 | V15: 0.1076 | W15: 0.0793 | X15: 0.065
A16: Cat2 Conf2 DL385 Gen10 plus | B16: =VLOOKUP(A16,'Lot 4 - Bordereau de prix'!A:B,2,FALSE) -> HPE ProLiant DL385 Gen10+ | C16: =VLOOKUP(A16,'Lot 4 - Bordereau de prix'!A:C,3,FALSE) -> P14278-B21 | D16: 1 | E16: =VLOOKUP(A16,'Lot 4 - Bordereau de prix'!A:F,6,FALSE) -> 1254.79 | F16: =ROUND($E16*F$2,2) -> 331.14 | G16: =ROUND($E16*G$2,2) -> 168.02 | H16: =ROUND($E16*H$2,2) -> 114.69 | I16: =ROUND($E16*I$2,2) -> 88.21 | J16: =U16 -> 0.2008 | K16: =$E16*J16 -> 251.96183 | L16: =V16 -> 0.1054 | M16: =$E16*L16 -> 132.25487 | N16: =W16 -> 0.0784 | O16: =$E16*N16 -> 98.375536 | P16: =X16 -> 0.0646 | Q16: =$E16*P16 -> 81.059434 | R16: Cat2 Conf2 DL385 Gen10 plus | U16: 0.2008 | V16: 0.1054 | W16: 0.0784 | X16: 0.0646
A17: Cat2 Conf7 DL365 Gen10 plus | B17: =VLOOKUP(A17,'Lot 4 - Bordereau de prix'!A:B,2,FALSE) -> HPE ProLiant DL365 Gen10+ | C17: =VLOOKUP(A17,'Lot 4 - Bordereau de prix'!A:C,3,FALSE) -> P38578-B21 | D17: 1 | E17: =VLOOKUP(A17,'Lot 4 - Bordereau de prix'!A:F,6,FALSE) -> 1467.9 | F17: =ROUND($E17*F$2,2) -> 387.38 | G17: =ROUND($E17*G$2,2) -> 196.55 | H17: =ROUND($E17*H$2,2) -> 134.17 | I17: =ROUND($E17*I$2,2) -> 103.19 | J17: =U17 -> 0.1987 | K17: =$E17*J17 -> 291.67173 | L17: =V17 -> 0.1045 | M17: =$E17*L17 -> 153.39555 | N17: =W17 -> 0.0779 | O17: =$E17*N17 -> 114.34941 | P17: =X17 -> 0.0644 | Q17: =$E17*P17 -> 94.53276 | R17: Cat2 Conf7 DL365 Gen10 plus | U17: 0.1987 | V17: 0.1045 | W17: 0.0779 | X17: 0.0644
A18: Cat2 Conf3 DL360 Gen10 | B18: =VLOOKUP(A18,'Lot 4 - Bordereau de prix'!A:B,2,FALSE) -> HPE ProLiant DL360 Gen10 | C18: =VLOOKUP(A18,'Lot 4 - Bordereau de prix'!A:C,3,FALSE) -> P19766-B21 | D18: 1 | E18: =VLOOKUP(A18,'Lot 4 - Bordereau de prix'!A:F,6,FALSE) -> 964.95 | F18: =ROUND($E18*F$2,2) -> 254.65 | G18: =ROUND($E18*G$2,2) -> 129.21 | H18: =ROUND($E18*H$2,2) -> 88.2 | I18: =ROUND($E18*I$2,2) -> 67.84 | J18: =U18 -> 0.2016 | K18: =$E18*J18 -> 194.53392 | L18: =V18 -> 0.1058 | M18: =$E18*L18 -> 102.09171 | N18: =W18 -> 0.0785 | O18: =$E18*N18 -> 75.748575 | P18: =X18 -> 0.0646 | Q18: =$E18*P18 -> 62.33577 | R18: Cat2 Conf3 DL360 Gen10 | U18: 0.2016 | V18: 0.1058 | W18: 0.0785 | X18: 0.0646
... A58: Cat5 Conf11 StorEver MSL 3040 | B58: =VLOOKUP(A58,'Lot 4 - Bordereau de prix'!A:B,2,FALSE) -> StoreEver MSL 3040 | C58: =VLOOKUP(A58,'Lot 4 - Bordereau de prix'!A:C,3,FALSE) -> Q6Q62B | D58: 1 | E58: =VLOOKUP(A58,'Lot 4 - Bordereau de prix'!A:F,6,FALSE) -> 5878.94 | F58: =ROUND($E58*F$2,2) -> 1551.45 | G58: =ROUND($E58*G$2,2) -> 787.19 | H58: =ROUND($E58*H$2,2) -> 537.34 | I58: =ROUND($E58*I$2,2) -> 413.29 | J58: =U58 -> 0.2013 | K58: =$E58*J58 -> 1183.4306 | L58: =V58 -> 0.1057 | M58: =$E58*L58 -> 621.40396 | N58: =W58 -> 0.0799 | O58: =$E58*N58 -> 469.72731 | P58: =X58 -> 0.0663 | Q58: =$E58*P58 -> 389.77372 | R58: Cat5 Conf11 StorEver MSL 3040 | U58: 0.2013 | V58: 0.1057 | W58: 0.0799 | X58: 0.0663

Sheet Loc Coefficients Crédit-Bail
A1: Category | B1: Equipment | C1: Type | D1: LRF12 | E1: LRF24 | F1: LRF36 | G1: LRF48
A2: PC_SE/PLX86 | B2: HPE ISS Servers (Apollo; SGI; Synergy; Superdome Flex; StoreEasy; Non Stop, Cloudline) | C2: Server | D2: 0.26392451 | E2: 0.13385372 | F2: 0.091350624 | G2: 0.070256845
A3: PC_SE/EDGE | B3: Edgeline/Moonshot | C3: Server | D3: 0.26392451 | E3: 0.13385372 | F3: 0.091350624 | G3: 0.070256845
A4: Store/PRIMERA | B4: Primera, Nimble and Alletra Storage Hardware; and Store SAN; includes MSA, Store Virtual, IAP(RISS), Storeonce, BX(VLS) | C4: Storage | D4: 0.26392451 | E4: 0.13385372 | F4: 0.091350624 | G4: 0.070256845
A5: Store/DTL | B5: StoreEver MSL and ESL Tape Libraries | C5: Storage | D5: 0.26392451 | E5: 0.13385372 | F5: 0.091350624 | G5: 0.070256845
A6: Store/Other | B6: 3rd Party Storage (EMC Storage, IBM, Lenovo, Pure Storage, Net App) & NAS Storage Appliance (Cisco NSS, QNAP) | C6: Storage | D6: 0.26392451 | E6: 0.13385372 | F6: 0.091350624 | G6: 0.070256845
A7: Netwo/HPEN | B7: Aruba Data Center Networking, Cisco & Arista | C7: Networking | D7: 0.26392451 | E7: 0.13385372 | F7: 0.091350624 | G7: 0.070256845
A8: Netwo/ARUBA | B8: Aruba Wireless | C8: Networking | D8: 0.26392451 | E8: 0.13385372 | F8: 0.091350624 | G8: 0.070256845
A9: SOFTCOST | B9: soft cost | C9: SOFT | D9: 0.26392451 | E9: 0.13385372 | F9: 0.091350624 | G9: 0.070256845

Sheet Loc Coefficients Location
A1: Category | B1: Equipment | C1: Type | D1: LRF12 | E1: LRF24 | F1: LRF36 | G1: LRF48
A2: PC_SE/PLX86 | B2: HPE ISS Servers (Apollo; SGI; Synergy; Superdome Flex; StoreEasy; Non Stop, Cloudline) | C2: Server | D2: 0.18651532 | E2: 0.099038653 | F2: 0.07542178 | G2: 0.063273484
A3: PC_SE/EDGE | B3: Edgeline/Moonshot | C3: Server | D3: 0.20925315 | E3: 0.11012243 | F3: 0.07949472 | G3: 0.065138183
A4: Store/PRIMERA | B4: Primera, Nimble and Alletra Storage Hardware; and Store SAN; includes MSA, Store Virtual, IAP(RISS), Storeonce, BX(VLS) | C4: Storage | D4: 0.19199024 | E4: 0.10177822 | F4: 0.077378408 | G4: 0.064774233
A5: Store/DTL | B5: StoreEver MSL and ESL Tape Libraries | C5: Storage | D5: 0.18383549 | E5: 0.097804969 | F5: 0.07665341 | G5: 0.065185764
A6: Store/Other | B6: 3rd Party Storage (EMC Storage, IBM, Lenovo, Pure Storage, Net App) & NAS Storage Appliance (Cisco NSS, QNAP) | C6: Storage | D6: 0.22517379 | E6: 0.11793884 | F6: 0.083826377 | G6: 0.068067471
