Workbook

Sheet Suivi de version
B2: Mise à jour Octobre 2023
B3: o Version initiale validée le 10/09/2021
B4: N1 V2 | C4: Ajoût numéros de références manquantes sur Descriptifs et prix existants
C5: Baisses de prix sur 2 références suites à erreurs typographiques
C6: Ajout (sans impact prix) de references logisitique de prises de rdv commandes sur toutes les configurations
C7: Correction de commentaires et descriptif suite à erreurs typographiques
C8: Ajout de passage de HDD vers SSD
A9: 44497 | B9: V3 | C9: Ajoût numéros de références manquantes sur Descriptifs et prix existants
C10: Baisse de prix sur 1 référence suite à erreur typographique
C11: Hausse de prix sur 1 référence suite à erreur typographique
C12: Changement de références logistique de l'interieur à quai/porte
C13: Ajout de passage livraison à l'interieur à 0€
C14: Ajout des references de prise de rdv a 1€
C15: Ajout des references livraison a l'etage a 1€
C16: Baisse de 2€ sur les configuration pour refleter ce surcout eventuel
C17: Suppression du cordon electrique par defaut
C18: Ajout des cordons 0,7m et 2m à 1€
C19: Baisse de 1€ sur les configuration pour refleter ce surcout eventuel
C20: Ajout des serveurs Intel Gen10+
C21: Ajout des serveurs AMD Gen10 +V2
... C28: Suppressions des ajouts impossible (cad avec passage uniquement)
A30: 44623 | B30: V4 | C30: Ajoût numéros de références manquantes sur Descriptifs et prix existants
C31: Correction de prix d'ajout ou passage pour respect prix passage (prix ajout - prix passage)
C32: Ajout de lignes support Nimble manquantes
C33: Ajout/Suppression/Mise à jour de reference SSD/Nvme obsoletes d'ici 3 mois
C34: Integration des SKUS HPE VMWare EDUC
C35: Integration des SKUS HPE MS EDUC
C36: Integration des SKUS Support 6 / 7 ans sur certaines references produits
C37: Ajout CPUs
C38: Suppression : Categorie 2 Options pour mutualisation
C39: Equilibrage de la ram des bundle par remplacement de barrette DIMM 16Go/32Go par 32Go/64Go avec répercution prix passage sur bundle
C40: Simplification des configurations Apollo 6500 avec configurations non éclatés (chassis et serveur) : prix final respecté avec logique ajout/passage
C41: Ajout Chassis Apollo Gen10+ Intel avec suppression de passage AMD avec Intel : prix final respecté avec logique ajout/passage
C42: Suppression temporaire des options sans garanti 5 ans embarqué (Nimble, Primera, Commutateurs,…)
A44: 44704 | B44: v5 | C44: Suppression des Ctrl RAID + disques durs des configurations (dégression des prix en conséquence)
C45: Ajout des rails kits dans les configurations (prise en compte dans prix bundle)
C46: Ajout derniers serveurs Gen10+ (ML30, DL20, Apollo 4200)
C47: Ajout Stockage Alletra, Qumulo
C48: Ajout références produit générique pour simplification BPU
C49: Ajout références stockage et réseau avec 5 ans intégrés
...

Sheet Lot4 - BPU
A2: Désignation Description des matériels | B2: Référence constructeur (le cas échéant) | C2: HPE SKU | D2: Quantités | E2: Tag | F2: TARIFS en €HT
A3: CATEGORIE 1 : Serveurs Edge ou Standard
A4: Désignation/Description des matériels | B4: Référence constructeur (le cas échéant) | C4: Numéro de référence | D4: Quantités | F4: TARIFS en €HT
A6: Cat1 Conf4 Microserver Gen10 Plus v2 | B6: HPE ProLiant MicroServer Gen10 plus v2 | C6: P54644-421 | F6: 573.47
A7: Serveur tour Ultra Micro mono-socket | B7: HPE ProLiant MicroServer Gen10 Plus v2 G6405 2-core 16GB-U VROC 4LFF-NHP 180W External PS Server | C7: P54644-421 | D7: 1
A8: 1 disque de 1 To 6G SATA 7.2K 3,5 pouces (LFF) Non Hot Plug | B8: HPE 1TB SATA 6G Business Critical 7.2K LFF RW 1-year Warranty Multi Vendor HDD | C8: 801882-B21 | D8: 1
A9: Kit pour carte d'administration HPE iLO | B9: HPE MicroServer Gen10 Plus iLO Enablement Kit | C9: P13788-B21 | D9: 1
A10: Carte d'administration HPE iLO avec API RESTful compatible IPMI v2.0 et Redfish. Licence en version Advanced avec toutes les options activées | B10: HPE iLO Advanced 1-server License with 1yr Support on iLO Licensed Features | C10: 512485-B21 | D10: 1
A11: Livraison devant la porte | B11: Livraison devant la porte | C11: AC114A | D11: 1
A12: Garantie 5 ans J+1 | B12: HPE 5 Year Tech Care Basic Service | C12: HU4B2A5 | D12: 1
A13: Garantie 5 ans H+4 ILO | B13: HPE 5 Year Tech Care Essential iLO Advance Non Blade Service | C13: HU4B2A5#7X4 | D13: 1
A14: Garantie 5 ans J+1 châssis | B14: HPE Microserver Gen10 Plus Support | C14: HU4B2A5#YKX | D14: 1
A16: Cat1 Conf5 DL20 Gen10 plus | B16: HPE ProLiant DL20 Gen10 plus | C16: P44109-B21 | F16: 310.47
A17: Serveur rack standard 1U DL20 Gen10+ mono-socket INTEL | B17: HPE DL20 Gen10+ 2LFF NHP CTO Svr | C17: P44109-B21 | D17: 1
A18: Processeur 64 bits Intel Xeon E-2314 (2,8 GHz de base / 4,50 Ghz Turbo / 4 cœurs / 4 threads / 8 Mo Smart Cache / 65W TDP) | B18: Intel Xeon E-2314 FIO CPU for HPE | C18: P45248-B21 | D18: 1
A19: Barrette mémoire de 16GB HPE Standard DDR4-3200 UDIMM | B19: HPE 16GB 1Rx8 PC4-3200AA-E STND Kit | C19: P43019-B21 | D19: 1
A20: 1 cage pour emplacement PCI | B20: HPE DL20 Gen10+ 2x8 LP FIO Riser Kit | C20: P46114-B21 | D20: 1
A21: Alimentation Titanium 800W | B21: HPE 800W FS Ti Ht Plg LH Pwr Sply Kit | C21: 865438-B21 | D21: 1
A22: Activation Alimentation redondante | B22: HPE ProLiant DL20 Gen10 Plus RPS FIO Enablement Kit | C22: P45948-B21 | D22: Cat
A23: Licence iLO en version Advanced avec toutes les options activées | B23: HPE iLO Adv 1-svr Lic 1yr Support | C23: 512485-B21 | D23: 1
A24: Suppression des câbles électriques par défaut | B24: HPE Remove Standard Power Cords | C24: 469774-409 | D24: 1
A25: 1 kit de rail pour rack | B25: HPE 1U Short Friction Rail Kit | C25: 775612-B21 | D25: 1
A26: Livraison devant la porte | B26: HPE Door/dock Small Delivery SVC | C26: AC111A | D26: 1
A27: Support 5 ans H+4 ILO | B27: HPE 5Y TC Ess iLO Adv Non BL SVC | C27: HW2P1E | D27: 1
A28: Garantie 5 ans J+1 châssis | B28: HPE 5Y TC Bas DL20 Gen10 Plus HW SVC | C28: H32ZWE | D28: 1
A31: Cat1 Conf10 DL325 Gen10 plus v2 | B31: HPE ProLiant DL325 Gen10 plus V2 | C31: P38471-B21 | F31: 969.28
A32: Serveur rack standard 1U mono-socket AMD | B32: HPE DL325 G10+ v2 8SFF CTO Svr | C32: P38471-B21 | D32: 1
A33: Processeur 64 bits AMD EPYC 7232P (3,1 GHz de base 8 cœurs / 16 threads) | B33: AMD EPYC 7232P Kit for DL325 Gen10+ v2 | C33: P39738-B21 | D33: 1
A34: Barrette mémoire de 32GB HPE DDR4-3200 RDIMM | B34: HPE 32GB 2Rx4 PC4-3200AA-R Smart Kit | C34: P07646-B21 | D34: 1
A35: Cage disque 8SFF | B35: HPE ProLiant DL325 Gen10 Plus v2 8SFF SAS/SATA BC FIO Backplane Kit | C35: P38473-B21 | D35: 1
A36: 2 ports Ethernet 10GbE Base-T OCP (intégré) | B36: BCM 57416 10GbE 2p BASE-T OCP3 Adptr | C36: P10097-B21 | D36: 1
A37: Alimentation Titanium 800W | B37: HPE 800W FS Ti Ht Plg LH Pwr Sply Kit | C37: 865438-B21 | D37: 1
A38: Licence iLO en version Advanced avec toutes les options activées | B38: HPE iLO Adv 1-svr Lic 1yr Support | C38: 512485-B21 | D38: 1
A39: Outil d'administration | B39: HPE GreenLake COM En 5y Up ProLiant aaS | C39: R7A12AAE | D39: 1
A40: Kit de câble SATA | B40: HPE DL325 G10+ v2 SATA FIO Cbl Kit | C40: P39134-B21 | D40: 1
A41: Kit Ventilateurs Standard | B41: HPE DL325 G10+ v2 Stnd FIO Fan Kit | C41: P41471-B21 | D41: 1
A42: Dissipateurs thermiques Haute Performance | B42: HPE DL325 G10+ v2 High Perf FIO HS Kit | C42: P41197-B21 | D42: 1
A43: Suppression des câbles électriques par défaut | B43: HPE Remove Standard Power Cords | C43: 469774-409 | D43: 1
... A47: Garantie 5 ans J+1 châssis | B47: HPE 5Y TC Bas DL325G10+V2 SVC | C47: HY5G1E | D47: 1
A50: Cat1 Conf6 Tour ML30 Gen10 plus | B50: HPE ProLiant ML30 Gen10 plus | C50: P44723-B21 | F50: 757.93
...

Sheet Lot4 - BPU DROM COM
H1: Les tarifs indiqués ci-après sont des prix plafonds et sont dégressifs selon les quantités approvisionnées sur une même commande. Le tarif indiqué correspond à un prix de transport DDP maritime. (le transport correspond en moyenne à 1/3 du prix). Les prix contractuels sont les prix des devis de transport fournis par IS2.
G3: Transport DDP Mer ou Services DROM COM | H3: 0.3526 | I3: 0.3526 | J3: 0.4633 | K3: 0.32185 | L3: 0.511475 | M3: 0.44075 | N3: 0.495075
A4: Désignation Description des matériels | B4: Référence constructeur (le cas échéant) | C4: HPE SKU | D4: Quantités | E4: Tag | F4: TARIFS en €HT | H4: Guadeloupe | I4: Martinique | J4: Guyane | K4: Réunion | L4: Mayotte | M4: Polynésie | N4: Nouvelle Calédonie | O4: Disponible DROMCOM
A5: CATEGORIE 1 : Serveurs Edge ou Standard | H5: =IF(AND(ISNUMBER($F5),$O5),$F5*H$3,"") | I5: =IF(AND(ISNUMBER($F5),$O5),$F5*I$3,"") | J5: =IF(AND(ISNUMBER($F5),$O5),$F5*J$3,"") | K5: =IF(AND(ISNUMBER($F5),$O5),$F5*K$3,"") | L5: =IF(AND(ISNUMBER($F5),$O5),$F5*L$3,"") | M5: =IF(AND(ISNUMBER($F5),$O5),$F5*M$3,"") | N5: =IF(AND(ISNUMBER($F5),$O5),$F5*N$3,"")
A6: Désignation/Description des matériels | B6: Référence constructeur (le cas échéant) | C6: Numéro de référence | D6: Quantités | F6: TARIFS en €HT | H6: =IF(AND(ISNUMBER($F6),$O6),$F6*H$3,"") | I6: =IF(AND(ISNUMBER($F6),$O6),$F6*I$3,"") | J6: =IF(AND(ISNUMBER($F6),$O6),$F6*J$3,"") | K6: =IF(AND(ISNUMBER($F6),$O6),$F6*K$3,"") | L6: =IF(AND(ISNUMBER($F6),$O6),$F6*L$3,"") | M6: =IF(AND(ISNUMBER($F6),$O6),$F6*M$3,"") | N6: =IF(AND(ISNUMBER($F6),$O6),$F6*N$3,"")
H7: =IF(AND(ISNUMBER($F7),$O7),$F7*H$3,"") | I7: =IF(AND(ISNUMBER($F7),$O7),$F7*I$3,"") | J7: =IF(AND(ISNUMBER($F7),$O7),$F7*J$3,"") | K7: =IF(AND(ISNUMBER($F7),$O7),$F7*K$3,"") | L7: =IF(AND(ISNUMBER($F7),$O7),$F7*L$3,"") | M7: =IF(AND(ISNUMBER($F7),$O7),$F7*M$3,"") | N7: =IF(AND(ISNUMBER($F7),$O7),$F7*N$3,"")
A8: Cat1 Conf4 Microserver Gen10 Plus v2 | B8: HPE ProLiant MicroServer Gen10 plus v2 | C8: P54644-421 | F8: 573.47 | H8: =IF(AND(ISNUMBER($F8),$O8),$F8*H$3,"") -> 202.20552 | I8: =IF(AND(ISNUMBER($F8),$O8),$F8*I$3,"") -> 202.20552 | J8: =IF(AND(ISNUMBER($F8),$O8),$F8*J$3,"") -> 265.68865 | K8: =IF(AND(ISNUMBER($F8),$O8),$F8*K$3,"") -> 184.57132 | L8: =IF(AND(ISNUMBER($F8),$O8),$F8*L$3,"") -> 293.31557 | M8: =IF(AND(ISNUMBER($F8),$O8),$F8*M$3,"") -> 252.7569 | N8: =IF(AND(ISNUMBER($F8),$O8),$F8*N$3,"") -> 283.91066 | O8: TRUE
A9: Serveur tour Ultra Micro mono-socket | B9: HPE ProLiant MicroServer Gen10 Plus v2 G6405 2-core 16GB-U VROC 4LFF-NHP 180W External PS Server | C9: P54644-421 | D9: 1 | H9: =IF(AND(ISNUMBER($F9),$O9),$F9*H$3,"") | I9: =IF(AND(ISNUMBER($F9),$O9),$F9*I$3,"") | J9: =IF(AND(ISNUMBER($F9),$O9),$F9*J$3,"") | K9: =IF(AND(ISNUMBER($F9),$O9),$F9*K$3,"") | L9: =IF(AND(ISNUMBER($F9),$O9),$F9*L$3,"") | M9: =IF(AND(ISNUMBER($F9),$O9),$F9*M$3,"") | N9: =IF(AND(ISNUMBER($F9),$O9),$F9*N$3,"")
A10: 1 disque de 1 To 6G SATA 7.2K 3,5 pouces (LFF) Non Hot Plug | B10: HPE 1TB SATA 6G Business Critical 7.2K LFF RW 1-year Warranty Multi Vendor HDD | C10: 801882-B21 | D10: 1 | H10: =IF(AND(ISNUMBER($F10),$O10),$F10*H$3,"") | I10: =IF(AND(ISNUMBER($F10),$O10),$F10*I$3,"") | J10: =IF(AND(ISNUMBER($F10),$O10),$F10*J$3,"") | K10: =IF(AND(ISNUMBER($F10),$O10),$F10*K$3,"") | L10: =IF(AND(ISNUMBER($F10),$O10),$F10*L$3,"") | M10: =IF(AND(ISNUMBER($F10),$O10),$F10*M$3,"") | N10: =IF(AND(ISNUMBER($F10),$O10),$F10*N$3,"")
A11: Kit pour carte d'administration HPE iLO | B11: HPE MicroServer Gen10 Plus iLO Enablement Kit | C11: P13788-B21 | D11: 1 | H11: =IF(AND(ISNUMBER($F11),$O11),$F11*H$3,"") | I11: =IF(AND(ISNUMBER($F11),$O11),$F11*I$3,"") | J11: =IF(AND(ISNUMBER($F11),$O11),$F11*J$3,"") | K11: =IF(AND(ISNUMBER($F11),$O11),$F11*K$3,"") | L11: =IF(AND(ISNUMBER($F11),$O11),$F11*L$3,"") | M11: =IF(AND(ISNUMBER($F11),$O11),$F11*M$3,"") | N11: =IF(AND(ISNUMBER($F11),$O11),$F11*N$3,"")
A12: Carte d'administration HPE iLO avec API RESTful compatible IPMI v2.0 et Redfish. Licence en version Advanced avec toutes les options activées | B12: HPE iLO Advanced 1-server License with 1yr Support on iLO Licensed Features | C12: 512485-B21 | D12: 1 | H12: =IF(AND(ISNUMBER($F12),$O12),$F12*H$3,"") | I12: =IF(AND(ISNUMBER($F12),$O12),$F12*I$3,"") | J12: =IF(AND(ISNUMBER($F12),$O12),$F12*J$3,"") | K12: =IF(AND(ISNUMBER($F12),$O12),$F12*K$3,"") | L12: =IF(AND(ISNUMBER($F12),$O12),$F12*L$3,"") | M12: =IF(AND(ISNUMBER($F12),$O12),$F12*M$3,"") | N12: =IF(AND(ISNUMBER($F12),$O12),$F12*N$3,"")
A13: Livraison devant la porte | B13: Livraison devant la porte | C13: AC114A | D13: 1 | H13: =IF(AND(ISNUMBER($F13),$O13),$F13*H$3,"") | I13: =IF(AND(ISNUMBER($F13),$O13),$F13*I$3,"") | J13: =IF(AND(ISNUMBER($F13),$O13),$F13*J$3,"") | K13: =IF(AND(ISNUMBER($F13),$O13),$F13*K$3,"") | L13: =IF(AND(ISNUMBER($F13),$O13),$F13*L$3,"") | M13: =IF(AND(ISNUMBER($F13),$O13),$F13*M$3,"") | N13: =IF(AND(ISNUMBER($F13),$O13),$F13*N$3,"")
A14: Garantie 5 ans J+1 | B14: HPE 5 Year Tech Care Basic Service | C14: HU4B2A5 | D14: 1 | H14: =IF(AND(ISNUMBER($F14),$O14),$F14*H$3,"") | I14: =IF(AND(ISNUMBER($F14),$O14),$F14*I$3,"") | J14: =IF(AND(ISNUMBER($F14),$O14),$F14*J$3,"") | K14: =IF(AND(ISNUMBER($F14),$O14),$F14*K$3,"") | L14: =IF(AND(ISNUMBER($F14),$O14),$F14*L$3,"") | M14: =IF(AND(ISNUMBER($F14),$O14),$F14*M$3,"") | N14: =IF(AND(ISNUMBER($F14),$O14),$F14*N$3,"")
A15: Garantie 5 ans H+4 ILO | B15: HPE 5 Year Tech Care Essential iLO Advance Non Blade Service | C15: HU4B2A5#7X4 | D15: 1 | H15: =IF(AND(ISNUMBER($F15),$O15),$F15*H$3,"") | I15: =IF(AND(ISNUMBER($F15),$O15),$F15*I$3,"") | J15: =IF(AND(ISNUMBER($F15),$O15),$F15*J$3,"") | K15: =IF(AND(ISNUMBER($F15),$O15),$F15*K$3,"") | L15: =IF(AND(ISNUMBER($F15),$O15),$F15*L$3,"") | M15: =IF(AND(ISNUMBER($F15),$O15),$F15*M$3,"") | N15: =IF(AND(ISNUMBER($F15),$O15),$F15*N$3,"")
A16: Garantie 5 ans J+1 châssis | B16: HPE Microserver Gen10 Plus Support | C16: HU4B2A5#YKX | D16: 1 | H16: =IF(AND(ISNUMBER($F16),$O16),$F16*H$3,"") | I16: =IF(AND(ISNUMBER($F16),$O16),$F16*I$3,"") | J16: =IF(AND(ISNUMBER($F16),$O16),$F16*J$3,"") | K16: =IF(AND(ISNUMBER($F16),$O16),$F16*K$3,"") | L16: =IF(AND(ISNUMBER($F16),$O16),$F16*L$3,"") | M16: =IF(AND(ISNUMBER($F16),$O16),$F16*M$3,"") | N16: =IF(AND(ISNUMBER($F16),$O16),$F16*N$3,"")
H17: =IF(AND(ISNUMBER($F17),$O17),$F17*H$3,"") | I17: =IF(AND(ISNUMBER($F17),$O17),$F17*I$3,"") | J17: =IF(AND(ISNUMBER($F17),$O17),$F17*J$3,"") | K17: =IF(AND(ISNUMBER($F17),$O17),$F17*K$3,"") | L17: =IF(AND(ISNUMBER($F17),$O17),$F17*L$3,"") | M17: =IF(AND(ISNUMBER($F17),$O17),$F17*M$3,"") | N17: =IF(AND(ISNUMBER($F17),$O17),$F17*N$3,"")
A18: Cat1 Conf5 DL20 Gen10 plus | B18: HPE ProLiant DL20 Gen10 plus | C18: P44109-B21 | F18: 310.47 | H18: =IF(AND(ISNUMBER($F18),$O18),$F18*H$3,"") -> 109.47172 | I18: =IF(AND(ISNUMBER($F18),$O18),$F18*I$3,"") -> 109.47172 | J18: =IF(AND(ISNUMBER($F18),$O18),$F18*J$3,"") -> 143.84075 | K18: =IF(AND(ISNUMBER($F18),$O18),$F18*K$3,"") -> 99.924769 | L18: =IF(AND(ISNUMBER($F18),$O18),$F18*L$3,"") -> 158.79764 | M18: =IF(AND(ISNUMBER($F18),$O18),$F18*M$3,"") -> 136.83965 | N18: =IF(AND(ISNUMBER($F18),$O18),$F18*N$3,"") -> 153.70594 | O18: TRUE
A19: Serveur rack standard 1U DL20 Gen10+ mono-socket INTEL | B19: HPE DL20 Gen10+ 2LFF NHP CTO Svr | C19: P44109-B21 | D19: 1 | H19: =IF(AND(ISNUMBER($F19),$O19),$F19*H$3,"") | I19: =IF(AND(ISNUMBER($F19),$O19),$F19*I$3,"") | J19: =IF(AND(ISNUMBER($F19),$O19),$F19*J$3,"") | K19: =IF(AND(ISNUMBER($F19),$O19),$F19*K$3,"") | L19: =IF(AND(ISNUMBER($F19),$O19),$F19*L$3,"") | M19: =IF(AND(ISNUMBER($F19),$O19),$F19*M$3,"") | N19: =IF(AND(ISNUMBER($F19),$O19),$F19*N$3,"")
A20: Processeur 64 bits Intel Xeon E-2314 (2,8 GHz de base / 4,50 Ghz Turbo / 4 cœurs / 4 threads / 8 Mo Smart Cache / 65W TDP) | B20: Intel Xeon E-2314 FIO CPU for HPE | C20: P45248-B21 | D20: 1 | H20: =IF(AND(ISNUMBER($F20),$O20),$F20*H$3,"") | I20: =IF(AND(ISNUMBER($F20),$O20),$F20*I$3,"") | J20: =IF(AND(ISNUMBER($F20),$O20),$F20*J$3,"") | K20: =IF(AND(ISNUMBER($F20),$O20),$F20*K$3,"") | L20: =IF(AND(ISNUMBER($F20),$O20),$F20*L$3,"") | M20: =IF(AND(ISNUMBER($F20),$O20),$F20*M$3,"") | N20: =IF(AND(ISNUMBER($F20),$O20),$F20*N$3,"")
A21: Barrette mémoire de 16GB HPE Standard DDR4-3200 UDIMM | B21: HPE 16GB 1Rx8 PC4-3200AA-E STND Kit | C21: P43019-B21 | D21: 1 | H21: =IF(AND(ISNUMBER($F21),$O21),$F21*H$3,"") | I21: =IF(AND(ISNUMBER($F21),$O21),$F21*I$3,"") | J21: =IF(AND(ISNUMBER($F21),$O21),$F21*J$3,"") | K21: =IF(AND(ISNUMBER($F21),$O21),$F21*K$3,"") | L21: =IF(AND(ISNUMBER($F21),$O21),$F21*L$3,"") | M21: =IF(AND(ISNUMBER($F21),$O21),$F21*M$3,"") | N21: =IF(AND(ISNUMBER($F21),$O21),$F21*N$3,"")
A22: 1 cage pour emplacement PCI | B22: HPE DL20 Gen10+ 2x8 LP FIO Riser Kit | C22: P46114-B21 | D22: 1 | H22: =IF(AND(ISNUMBER($F22),$O22),$F22*H$3,"") | I22: =IF(AND(ISNUMBER($F22),$O22),$F22*I$3,"") | J22: =IF(AND(ISNUMBER($F22),$O22),$F22*J$3,"") | K22: =IF(AND(ISNUMBER($F22),$O22),$F22*K$3,"") | L22: =IF(AND(ISNUMBER($F22),$O22),$F22*L$3,"") | M22: =IF(AND(ISNUMBER($F22),$O22),$F22*M$3,"") | N22: =IF(AND(ISNUMBER($F22),$O22),$F22*N$3,"")
A23: Alimentation Titanium 800W | B23: HPE 800W FS Ti Ht Plg LH Pwr Sply Kit | C23: 865438-B21 | D23: 1 | H23: =IF(AND(ISNUMBER($F23),$O23),$F23*H$3,"") | I23: =IF(AND(ISNUMBER($F23),$O23),$F23*I$3,"") | J23: =IF(AND(ISNUMBER($F23),$O23),$F23*J$3,"") | K23: =IF(AND(ISNUMBER($F23),$O23),$F23*K$3,"") | L23: =IF(AND(ISNUMBER($F23),$O23),$F23*L$3,"") | M23: =IF(AND(ISNUMBER($F23),$O23),$F23*M$3,"") | N23: =IF(AND(ISNUMBER($F23),$O23),$F23*N$3,"")
A24: Activation Alimentation redondante | B24: HPE ProLiant DL20 Gen10 Plus RPS FIO Enablement Kit | C24: P45948-B21 | D24: Cat | H24: =IF(AND(ISNUMBER($F24),$O24),$F24*H$3,"") | I24: =IF(AND(ISNUMBER($F24),$O24),$F24*I$3,"") | J24: =IF(AND(ISNUMBER($F24),$O24),$F24*J$3,"") | K24: =IF(AND(ISNUMBER($F24),$O24),$F24*K$3,"") | L24: =IF(AND(ISNUMBER($F24),$O24),$F24*L$3,"") | M24: =IF(AND(ISNUMBER($F24),$O24),$F24*M$3,"") | N24: =IF(AND(ISNUMBER($F24),$O24),$F24*N$3,"")
A25: Licence iLO en version Advanced avec toutes les options activées | B25: HPE iLO Adv 1-svr Lic 1yr Support | C25: 512485-B21 | D25: 1 | H25: =IF(AND(ISNUMBER($F25),$O25),$F25*H$3,"") | I25: =IF(AND(ISNUMBER($F25),$O25),$F25*I$3,"") | J25: =IF(AND(ISNUMBER($F25),$O25),$F25*J$3,"") | K25: =IF(AND(ISNUMBER($F25),$O25),$F25*K$3,"") | L25: =IF(AND(ISNUMBER($F25),$O25),$F25*L$3,"") | M25: =IF(AND(ISNUMBER($F25),$O25),$F25*M$3,"") | N25: =IF(AND(ISNUMBER($F25),$O25),$F25*N$3,"")
A26: Suppression des câbles électriques par défaut | B26: HPE Remove Standard Power Cords | C26: 469774-409 | D26: 1 | H26: =IF(AND(ISNUMBER($F26),$O26),$F26*H$3,"") | I26: =IF(AND(ISNUMBER($F26),$O26),$F26*I$3,"") | J26: =IF(AND(ISNUMBER($F26),$O26),$F26*J$3,"") | K26: =IF(AND(ISNUMBER($F26),$O26),$F26*K$3,"") | L26: =IF(AND(ISNUMBER($F26),$O26),$F26*L$3,"") | M26: =IF(AND(ISNUMBER($F26),$O26),$F26*M$3,"") | N26: =IF(AND(ISNUMBER($F26),$O26),$F26*N$3,"")
A27: 1 kit de rail pour rack | B27: HPE 1U Short Friction Rail Kit | C27: 775612-B21 | D27: 1 | H27: =IF(AND(ISNUMBER($F27),$O27),$F27*H$3,"") | I27: =IF(AND(ISNUMBER($F27),$O27),$F27*I$3,"") | J27: =IF(AND(ISNUMBER($F27),$O27),$F27*J$3,"") | K27: =IF(AND(ISNUMBER($F27),$O27),$F27*K$3,"") | L27: =IF(AND(ISNUMBER($F27),$O27),$F27*L$3,"") | M27: =IF(AND(ISNUMBER($F27),$O27),$F27*M$3,"") | N27: =IF(AND(ISNUMBER($F27),$O27),$F27*N$3,"")
A28: Livraison devant la porte | B28: HPE Door/dock Small Delivery SVC | C28: AC111A | D28: 1 | H28: =IF(AND(ISNUMBER($F28),$O28),$F28*H$3,"") | I28: =IF(AND(ISNUMBER($F28),$O28),$F28*I$3,"") | J28: =IF(AND(ISNUMBER($F28),$O28),$F28*J$3,"") | K28: =IF(AND(ISNUMBER($F28),$O28),$F28*K$3,"") | L28: =IF(AND(ISNUMBER($F28),$O28),$F28*L$3,"") | M28: =IF(AND(ISNUMBER($F28),$O28),$F28*M$3,"") | N28: =IF(AND(ISNUMBER($F28),$O28),$F28*N$3,"")
A29: Support 5 ans H+4 ILO | B29: HPE 5Y TC Ess iLO Adv Non BL SVC | C29: HW2P1E | D29: 1 | H29: =IF(AND(ISNUMBER($F29),$O29),$F29*H$3,"") | I29: =IF(AND(ISNUMBER($F29),$O29),$F29*I$3,"") | J29: =IF(AND(ISNUMBER($F29),$O29),$F29*J$3,"") | K29: =IF(AND(ISNUMBER($F29),$O29),$F29*K$3,"") | L29: =IF(AND(ISNUMBER($F29),$O29),$F29*L$3,"") | M29: =IF(AND(ISNUMBER($F29),$O29),$F29*M$3,"") | N29: =IF(AND(ISNUMBER($F29),$O29),$F29*N$3,"")
A30: Garantie 5 ans J+1 châssis | B30: HPE 5Y TC Bas DL20 Gen10 Plus HW SVC | C30: H32ZWE | D30: 1 | H30: =IF(AND(ISNUMBER($F30),$O30),$F30*H$3,"") | I30: =IF(AND(ISNUMBER($F30),$O30),$F30*I$3,"") | J30: =IF(AND(ISNUMBER($F30),$O30),$F30*J$3,"") | K30: =IF(AND(ISNUMBER($F30),$O30),$F30*K$3,"") | L30: =IF(AND(ISNUMBER($F30),$O30),$F30*L$3,"") | M30: =IF(AND(ISNUMBER($F30),$O30),$F30*M$3,"") | N30: =IF(AND(ISNUMBER($F30),$O30),$F30*N$3,"")
H31: =IF(AND(ISNUMBER($F31),$O31),$F31*H$3,"") | I31: =IF(AND(ISNUMBER($F31),$O31),$F31*I$3,"") | J31: =IF(AND(ISNUMBER($F31),$O31),$F31*J$3,"") | K31: =IF(AND(ISNUMBER($F31),$O31),$F31*K$3,"") | L31: =IF(AND(ISNUMBER($F31),$O31),$F31*L$3,"") | M31: =IF(AND(ISNUMBER($F31),$O31),$F31*M$3,"") | N31: =IF(AND(ISNUMBER($F31),$O31),$F31*N$3,"")
H32: =IF(AND(ISNUMBER($F32),$O32),$F32*H$3,"") | I32: =IF(AND(ISNUMBER($F32),$O32),$F32*I$3,"") | J32: =IF(AND(ISNUMBER($F32),$O32),$F32*J$3,"") | K32: =IF(AND(ISNUMBER($F32),$O32),$F32*K$3,"") | L32: =IF(AND(ISNUMBER($F32),$O32),$F32*L$3,"") | M32: =IF(AND(ISNUMBER($F32),$O32),$F32*M$3,"") | N32: =IF(AND(ISNUMBER($F32),$O32),$F32*N$3,"")
A33: Cat1 Conf10 DL325 Gen10 plus v2 | B33: HPE ProLiant DL325 Gen10 plus V2 | C33: P38471-B21 | F33: 969.28 | H33: =IF(AND(ISNUMBER($F33),$O33),$F33*H$3,"") -> 341.76813 | I33: =IF(AND(ISNUMBER($F33),$O33),$F33*I$3,"") -> 341.76813 | J33: =IF(AND(ISNUMBER($F33),$O33),$F33*J$3,"") -> 449.06742 | K33: =IF(AND(ISNUMBER($F33),$O33),$F33*K$3,"") -> 311.96277 | L33: =IF(AND(ISNUMBER($F33),$O33),$F33*L$3,"") -> 495.76249 | M33: =IF(AND(ISNUMBER($F33),$O33),$F33*M$3,"") -> 427.21016 | N33: =IF(AND(ISNUMBER($F33),$O33),$F33*N$3,"") -> 479.8663 | O33: TRUE
A34: Serveur rack standard 1U mono-socket AMD | B34: HPE DL325 G10+ v2 8SFF CTO Svr | C34: P38471-B21 | D34: 1 | H34: =IF(AND(ISNUMBER($F34),$O34),$F34*H$3,"") | I34: =IF(AND(ISNUMBER($F34),$O34),$F34*I$3,"") | J34: =IF(AND(ISNUMBER($F34),$O34),$F34*J$3,"") | K34: =IF(AND(ISNUMBER($F34),$O34),$F34*K$3,"") | L34: =IF(AND(ISNUMBER($F34),$O34),$F34*L$3,"") | M34: =IF(AND(ISNUMBER($F34),$O34),$F34*M$3,"") | N34: =IF(AND(ISNUMBER($F34),$O34),$F34*N$3,"")
A35: Processeur 64 bits AMD EPYC 7232P (3,1 GHz de base 8 cœurs / 16 threads) | B35: AMD EPYC 7232P Kit for DL325 Gen10+ v2 | C35: P39738-B21 | D35: 1 | H35: =IF(AND(ISNUMBER($F35),$O35),$F35*H$3,"") | I35: =IF(AND(ISNUMBER($F35),$O35),$F35*I$3,"") | J35: =IF(AND(ISNUMBER($F35),$O35),$F35*J$3,"") | K35: =IF(AND(ISNUMBER($F35),$O35),$F35*K$3,"") | L35: =IF(AND(ISNUMBER($F35),$O35),$F35*L$3,"") | M35: =IF(AND(ISNUMBER($F35),$O35),$F35*M$3,"") | N35: =IF(AND(ISNUMBER($F35),$O35),$F35*N$3,"")
A36: Barrette mémoire de 32GB HPE DDR4-3200 RDIMM | B36: HPE 32GB 2Rx4 PC4-3200AA-R Smart Kit | C36: P07646-B21 | D36: 1 | H36: =IF(AND(ISNUMBER($F36),$O36),$F36*H$3,"") | I36: =IF(AND(ISNUMBER($F36),$O36),$F36*I$3,"") | J36: =IF(AND(ISNUMBER($F36),$O36),$F36*J$3,"") | K36: =IF(AND(ISNUMBER($F36),$O36),$F36*K$3,"") | L36: =IF(AND(ISNUMBER($F36),$O36),$F36*L$3,"") | M36: =IF(AND(ISNUMBER($F36),$O36),$F36*M$3,"") | N36: =IF(AND(ISNUMBER($F36),$O36),$F36*N$3,"")
A37: Cage disque 8SFF | B37: HPE ProLiant DL325 Gen10 Plus v2 8SFF SAS/SATA BC FIO Backplane Kit | C37: P38473-B21 | D37: 1 | H37: =IF(AND(ISNUMBER($F37),$O37),$F37*H$3,"") | I37: =IF(AND(ISNUMBER($F37),$O37),$F37*I$3,"") | J37: =IF(AND(ISNUMBER($F37),$O37),$F37*J$3,"") | K37: =IF(AND(ISNUMBER($F37),$O37),$F37*K$3,"") | L37: =IF(AND(ISNUMBER($F37),$O37),$F37*L$3,"") | M37: =IF(AND(ISNUMBER($F37),$O37),$F37*M$3,"") | N37: =IF(AND(ISNUMBER($F37),$O37),$F37*N$3,"")
A38: 2 ports Ethernet 10GbE Base-T OCP (intégré) | B38: BCM 57416 10GbE 2p BASE-T OCP3 Adptr | C38: P10097-B21 | D38: 1 | H38: =IF(AND(ISNUMBER($F38),$O38),$F38*H$3,"") | I38: =IF(AND(ISNUMBER($F38),$O38),$F38*I$3,"") | J38: =IF(AND(ISNUMBER($F38),$O38),$F38*J$3,"") | K38: =IF(AND(ISNUMBER($F38),$O38),$F38*K$3,"") | L38: =IF(AND(ISNUMBER($F38),$O38),$F38*L$3,"") | M38: =IF(AND(ISNUMBER($F38),$O38),$F38*M$3,"") | N38: =IF(AND(ISNUMBER($F38),$O38),$F38*N$3,"")
A39: Alimentation Titanium 800W | B39: HPE 800W FS Ti Ht Plg LH Pwr Sply Kit | C39: 865438-B21 | D39: 1 | H39: =IF(AND(ISNUMBER($F39),$O39),$F39*H$3,"") | I39: =IF(AND(ISNUMBER($F39),$O39),$F39*I$3,"") | J39: =IF(AND(ISNUMBER($F39),$O39),$F39*J$3,"") | K39: =IF(AND(ISNUMBER($F39),$O39),$F39*K$3,"") | L39: =IF(AND(ISNUMBER($F39),$O39),$F39*L$3,"") | M39: =IF(AND(ISNUMBER($F39),$O39),$F39*M$3,"") | N39: =IF(AND(ISNUMBER($F39),$O39),$F39*N$3,"")
A40: Licence iLO en version Advanced avec toutes les options activées | B40: HPE iLO Adv 1-svr Lic 1yr Support | C40: 512485-B21 | D40: 1 | H40: =IF(AND(ISNUMBER($F40),$O40),$F40*H$3,"") | I40: =IF(AND(ISNUMBER($F40),$O40),$F40*I$3,"") | J40: =IF(AND(ISNUMBER($F40),$O40),$F40*J$3,"") | K40: =IF(AND(ISNUMBER($F40),$O40),$F40*K$3,"") | L40: =IF(AND(ISNUMBER($F40),$O40),$F40*L$3,"") | M40: =IF(AND(ISNUMBER($F40),$O40),$F40*M$3,"") | N40: =IF(AND(ISNUMBER($F40),$O40),$F40*N$3,"")
A41: Outil d'administration | B41: HPE GreenLake COM En 5y Up ProLiant aaS | C41: R7A12AAE | D41: 1 | H41: =IF(AND(ISNUMBER($F41),$O41),$F41*H$3,"") | I41: =IF(AND(ISNUMBER($F41),$O41),$F41*I$3,"") | J41: =IF(AND(ISNUMBER($F41),$O41),$F41*J$3,"") | K41: =IF(AND(ISNUMBER($F41),$O41),$F41*K$3,"") | L41: =IF(AND(ISNUMBER($F41),$O41),$F41*L$3,"") | M41: =IF(AND(ISNUMBER($F41),$O41),$F41*M$3,"") | N41: =IF(AND(ISNUMBER($F41),$O41),$F41*N$3,"")
...

Sheet Lot4 - BPU Location
G1: Coefficients en Crédit-Bail | H1: 0.26888624 | I1: 0.13836099 | J1: 0.095025056
A2: Désignation Description des matériels | B2: Référence constructeur (le cas échéant) | C2: HPE SKU | D2: Quantités | E2: Tag | F2: TARIFS en €HT | G2: Références de Location | H2: Crédit Bail 1 An Loyer Trimestriel €HT (4 Trimestres) | I2: Crédit Bail 2 Ans Loyer Trimestriel €HT (8 Trimestres) | J2: Crédit Bail 3 Ans Loyer Trimestriel €HT (12 Trimestres) | K2: Coefficient Locatif 1 An (4 Trimestres) | L2: Loyer Trimestriel 1 An (4 Trimestres) €HT | M2: Coefficient Locatif 2 Ans (8 Trimestres) | N2: Loyer Trimestriel 2 Ans (8 Trimestres) €HT | O2: Coefficient Locatif 3 Ans (12 Trimestres) | P2: Loyer Trimestriel 3 Ans (12 Trimestres) €HT
A3: CATEGORIE 1 : Serveurs Edge ou Standard | H3: =IF(ISNUMBER($F3),ROUND($F3*H$1,2),"") | I3: =IF(ISNUMBER($F3),ROUND($F3*I$1,2),"") | J3: =IF(ISNUMBER($F3),ROUND($F3*J$1,2),"") | K3: =IF(ISNUMBER(F3),IF(G3="",VLOOKUP($A3,'Loc Coefficients Config'!$A:$G,7,FALSE),VLOOKUP(G3,'Loc Coefficients Location'!A:D,4,FALSE)),"") | L3: =IF(ISNUMBER(K3),ROUND($F3*K3,2),"") | M3: =IF(ISNUMBER(F3),IF(G3="",VLOOKUP($A3,'Loc Coefficients Config'!$A:$H,8,FALSE),VLOOKUP(G3,'Loc Coefficients Location'!A:E,5,FALSE)),"") | N3: =IF(ISNUMBER(M3),ROUND($F3*M3,2),"") | O3: =IF(ISNUMBER(F3),IF(G3="",VLOOKUP($A3,'Loc Coefficients Config'!$A:$I,9,FALSE),VLOOKUP(G3,'Loc Coefficients Location'!A:F,6,FALSE)),"") | P3: =IF(ISNUMBER(O3),ROUND($F3*O3,2),"")
A4: Désignation/Description des matériels | B4: Référence constructeur (le cas échéant) | C4: Numéro de référence | D4: Quantités | F4: TARIFS en €HT | H4: =IF(ISNUMBER($F4),ROUND($F4*H$1,2),"") | I4: =IF(ISNUMBER($F4),ROUND($F4*I$1,2),"") | J4: =IF(ISNUMBER($F4),ROUND($F4*J$1,2),"") | K4: =IF(ISNUMBER(F4),IF(G4="",VLOOKUP($A4,'Loc Coefficients Config'!$A:$G,7,FALSE),VLOOKUP(G4,'Loc Coefficients Location'!A:D,4,FALSE)),"") | L4: =IF(ISNUMBER(K4),ROUND($F4*K4,2),"") | M4: =IF(ISNUMBER(F4),IF(G4="",VLOOKUP($A4,'Loc Coefficients Config'!$A:$H,8,FALSE),VLOOKUP(G4,'Loc Coefficients Location'!A:E,5,FALSE)),"") | N4: =IF(ISNUMBER(M4),ROUND($F4*M4,2),"") | O4: =IF(ISNUMBER(F4),IF(G4="",VLOOKUP($A4,'Loc Coefficients Config'!$A:$I,9,FALSE),VLOOKUP(G4,'Loc Coefficients Location'!A:F,6,FALSE)),"") | P4: =IF(ISNUMBER(O4),ROUND($F4*O4,2),"")
H5: =IF(ISNUMBER($F5),ROUND($F5*H$1,2),"") | I5: =IF(ISNUMBER($F5),ROUND($F5*I$1,2),"") | J5: =IF(ISNUMBER($F5),ROUND($F5*J$1,2),"") | K5: =IF(ISNUMBER(F5),IF(G5="",VLOOKUP($A5,'Loc Coefficients Config'!$A:$G,7,FALSE),VLOOKUP(G5,'Loc Coefficients Location'!A:D,4,FALSE)),"") | L5: =IF(ISNUMBER(K5),ROUND($F5*K5,2),"") | M5: =IF(ISNUMBER(F5),IF(G5="",VLOOKUP($A5,'Loc Coefficients Config'!$A:$H,8,FALSE),VLOOKUP(G5,'Loc Coefficients Location'!A:E,5,FALSE)),"") | N5: =IF(ISNUMBER(M5),ROUND($F5*M5,2),"") | O5: =IF(ISNUMBER(F5),IF(G5="",VLOOKUP($A5,'Loc Coefficients Config'!$A:$I,9,FALSE),VLOOKUP(G5,'Loc Coefficients Location'!A:F,6,FALSE)),"") | P5: =IF(ISNUMBER(O5),ROUND($F5*O5,2),"")
A6: Cat1 Conf4 Microserver Gen10 Plus v2 | B6: HPE ProLiant MicroServer Gen10 plus v2 | C6: P54644-421 | F6: 573.47 | H6: =IF(ISNUMBER($F6),ROUND($F6*H$1,2),"") -> 154.2 | I6: =IF(ISNUMBER($F6),ROUND($F6*I$1,2),"") -> 79.35 | J6: =IF(ISNUMBER($F6),ROUND($F6*J$1,2),"") -> 54.49 | K6: =IF(ISNUMBER(F6),IF(G6="",VLOOKUP($A6,'Loc Coefficients Config'!$A:$G,7,FALSE),VLOOKUP(G6,'Loc Coefficients Location'!A:D,4,FALSE)),"") -> 0.19408936 | L6: =IF(ISNUMBER(K6),ROUND($F6*K6,2),"") -> 111.3 | M6: =IF(ISNUMBER(F6),IF(G6="",VLOOKUP($A6,'Loc Coefficients Config'!$A:$H,8,FALSE),VLOOKUP(G6,'Loc Coefficients Location'!A:E,5,FALSE)),"") -> 0.10502487 | N6: =IF(ISNUMBER(M6),ROUND($F6*M6,2),"") -> 60.23 | O6: =IF(ISNUMBER(F6),IF(G6="",VLOOKUP($A6,'Loc Coefficients Config'!$A:$I,9,FALSE),VLOOKUP(G6,'Loc Coefficients Location'!A:F,6,FALSE)),"") -> 0.080002776 | P6: =IF(ISNUMBER(O6),ROUND($F6*O6,2),"") -> 45.88
A7: Serveur tour Ultra Micro mono-socket | B7: HPE ProLiant MicroServer Gen10 Plus v2 G6405 2-core 16GB-U VROC 4LFF-NHP 180W External PS Server | C7: P54644-421 | D7: 1 | G7: PC_SE/PLX86 | H7: =IF(ISNUMBER($F7),ROUND($F7*H$1,2),"") | I7: =IF(ISNUMBER($F7),ROUND($F7*I$1,2),"") | J7: =IF(ISNUMBER($F7),ROUND($F7*J$1,2),"") | K7: =IF(ISNUMBER(F7),IF(G7="",VLOOKUP($A7,'Loc Coefficients Config'!$A:$G,7,FALSE),VLOOKUP(G7,'Loc Coefficients Location'!A:D,4,FALSE)),"") | L7: =IF(ISNUMBER(K7),ROUND($F7*K7,2),"") | M7: =IF(ISNUMBER(F7),IF(G7="",VLOOKUP($A7,'Loc Coefficients Config'!$A:$H,8,FALSE),VLOOKUP(G7,'Loc Coefficients Location'!A:E,5,FALSE)),"") | N7: =IF(ISNUMBER(M7),ROUND($F7*M7,2),"") | O7: =IF(ISNUMBER(F7),IF(G7="",VLOOKUP($A7,'Loc Coefficients Config'!$A:$I,9,FALSE),VLOOKUP(G7,'Loc Coefficients Location'!A:F,6,FALSE)),"") | P7: =IF(ISNUMBER(O7),ROUND($F7*O7,2),"")
A8: 1 disque de 1 To 6G SATA 7.2K 3,5 pouces (LFF) Non Hot Plug | B8: HPE 1TB SATA 6G Business Critical 7.2K LFF RW 1-year Warranty Multi Vendor HDD | C8: 801882-B21 | D8: 1 | G8: PC_SE/PLX86 | H8: =IF(ISNUMBER($F8),ROUND($F8*H$1,2),"") | I8: =IF(ISNUMBER($F8),ROUND($F8*I$1,2),"") | J8: =IF(ISNUMBER($F8),ROUND($F8*J$1,2),"") | K8: =IF(ISNUMBER(F8),IF(G8="",VLOOKUP($A8,'Loc Coefficients Config'!$A:$G,7,FALSE),VLOOKUP(G8,'Loc Coefficients Location'!A:D,4,FALSE)),"") | L8: =IF(ISNUMBER(K8),ROUND($F8*K8,2),"") | M8: =IF(ISNUMBER(F8),IF(G8="",VLOOKUP($A8,'Loc Coefficients Config'!$A:$H,8,FALSE),VLOOKUP(G8,'Loc Coefficients Location'!A:E,5,FALSE)),"") | N8: =IF(ISNUMBER(M8),ROUND($F8*M8,2),"") | O8: =IF(ISNUMBER(F8),IF(G8="",VLOOKUP($A8,'Loc Coefficients Config'!$A:$I,9,FALSE),VLOOKUP(G8,'Loc Coefficients Location'!A:F,6,FALSE)),"") | P8: =IF(ISNUMBER(O8),ROUND($F8*O8,2),"")
A9: Kit pour carte d'administration HPE iLO | B9: HPE MicroServer Gen10 Plus iLO Enablement Kit | C9: P13788-B21 | D9: 1 | G9: PC_SE/PLX86 | H9: =IF(ISNUMBER($F9),ROUND($F9*H$1,2),"") | I9: =IF(ISNUMBER($F9),ROUND($F9*I$1,2),"") | J9: =IF(ISNUMBER($F9),ROUND($F9*J$1,2),"") | K9: =IF(ISNUMBER(F9),IF(G9="",VLOOKUP($A9,'Loc Coefficients Config'!$A:$G,7,FALSE),VLOOKUP(G9,'Loc Coefficients Location'!A:D,4,FALSE)),"") | L9: =IF(ISNUMBER(K9),ROUND($F9*K9,2),"") | M9: =IF(ISNUMBER(F9),IF(G9="",VLOOKUP($A9,'Loc Coefficients Config'!$A:$H,8,FALSE),VLOOKUP(G9,'Loc Coefficients Location'!A:E,5,FALSE)),"") | N9: =IF(ISNUMBER(M9),ROUND($F9*M9,2),"") | O9: =IF(ISNUMBER(F9),IF(G9="",VLOOKUP($A9,'Loc Coefficients Config'!$A:$I,9,FALSE),VLOOKUP(G9,'Loc Coefficients Location'!A:F,6,FALSE)),"") | P9: =IF(ISNUMBER(O9),ROUND($F9*O9,2),"")
A10: Carte d'administration HPE iLO avec API RESTful compatible IPMI v2.0 et Redfish. Licence en version Advanced avec toutes les options activées | B10: HPE iLO Advanced 1-server License with 1yr Support on iLO Licensed Features | C10: 512485-B21 | D10: 1 | G10: SOFTCOST | H10: =IF(ISNUMBER($F10),ROUND($F10*H$1,2),"") | I10: =IF(ISNUMBER($F10),ROUND($F10*I$1,2),"") | J10: =IF(ISNUMBER($F10),ROUND($F10*J$1,2),"") | K10: =IF(ISNUMBER(F10),IF(G10="",VLOOKUP($A10,'Loc Coefficients Config'!$A:$G,7,FALSE),VLOOKUP(G10,'Loc Coefficients Location'!A:D,4,FALSE)),"") | L10: =IF(ISNUMBER(K10),ROUND($F10*K10,2),"") | M10: =IF(ISNUMBER(F10),IF(G10="",VLOOKUP($A10,'Loc Coefficients Config'!$A:$H,8,FALSE),VLOOKUP(G10,'Loc Coefficients Location'!A:E,5,FALSE)),"") | N10: =IF(ISNUMBER(M10),ROUND($F10*M10,2),"") | O10: =IF(ISNUMBER(F10),IF(G10="",VLOOKUP($A10,'Loc Coefficients Config'!$A:$I,9,FALSE),VLOOKUP(G10,'Loc Coefficients Location'!A:F,6,FALSE)),"") | P10: =IF(ISNUMBER(O10),ROUND($F10*O10,2),"")
A11: Livraison devant la porte | B11: Livraison devant la porte | C11: AC114A | D11: 1 | G11: SOFTCOST | H11: =IF(ISNUMBER($F11),ROUND($F11*H$1,2),"") | I11: =IF(ISNUMBER($F11),ROUND($F11*I$1,2),"") | J11: =IF(ISNUMBER($F11),ROUND($F11*J$1,2),"") | K11: =IF(ISNUMBER(F11),IF(G11="",VLOOKUP($A11,'Loc Coefficients Config'!$A:$G,7,FALSE),VLOOKUP(G11,'Loc Coefficients Location'!A:D,4,FALSE)),"") | L11: =IF(ISNUMBER(K11),ROUND($F11*K11,2),"") | M11: =IF(ISNUMBER(F11),IF(G11="",VLOOKUP($A11,'Loc Coefficients Config'!$A:$H,8,FALSE),VLOOKUP(G11,'Loc Coefficients Location'!A:E,5,FALSE)),"") | N11: =IF(ISNUMBER(M11),ROUND($F11*M11,2),"") | O11: =IF(ISNUMBER(F11),IF(G11="",VLOOKUP($A11,'Loc Coefficients Config'!$A:$I,9,FALSE),VLOOKUP(G11,'Loc Coefficients Location'!A:F,6,FALSE)),"") | P11: =IF(ISNUMBER(O11),ROUND($F11*O11,2),"")
A12: Garantie 5 ans J+1 | B12: HPE 5 Year Tech Care Basic Service | C12: HU4B2A5 | D12: 1 | G12: SOFT/MAINT | H12: =IF(ISNUMBER($F12),ROUND($F12*H$1,2),"") | I12: =IF(ISNUMBER($F12),ROUND($F12*I$1,2),"") | J12: =IF(ISNUMBER($F12),ROUND($F12*J$1,2),"") | K12: =IF(ISNUMBER(F12),IF(G12="",VLOOKUP($A12,'Loc Coefficients Config'!$A:$G,7,FALSE),VLOOKUP(G12,'Loc Coefficients Location'!A:D,4,FALSE)),"") | L12: =IF(ISNUMBER(K12),ROUND($F12*K12,2),"") | M12: =IF(ISNUMBER(F12),IF(G12="",VLOOKUP($A12,'Loc Coefficients Config'!$A:$H,8,FALSE),VLOOKUP(G12,'Loc Coefficients Location'!A:E,5,FALSE)),"") | N12: =IF(ISNUMBER(M12),ROUND($F12*M12,2),"") | O12: =IF(ISNUMBER(F12),IF(G12="",VLOOKUP($A12,'Loc Coefficients Config'!$A:$I,9,FALSE),VLOOKUP(G12,'Loc Coefficients Location'!A:F,6,FALSE)),"") | P12: =IF(ISNUMBER(O12),ROUND($F12*O12,2),"")
A13: Garantie 5 ans H+4 ILO | B13: HPE 5 Year Tech Care Essential iLO Advance Non Blade Service | C13: HU4B2A5#7X4 | D13: 1 | G13: SOFT/MAINT | H13: =IF(ISNUMBER($F13),ROUND($F13*H$1,2),"") | I13: =IF(ISNUMBER($F13),ROUND($F13*I$1,2),"") | J13: =IF(ISNUMBER($F13),ROUND($F13*J$1,2),"") | K13: =IF(ISNUMBER(F13),IF(G13="",VLOOKUP($A13,'Loc Coefficients Config'!$A:$G,7,FALSE),VLOOKUP(G13,'Loc Coefficients Location'!A:D,4,FALSE)),"") | L13: =IF(ISNUMBER(K13),ROUND($F13*K13,2),"") | M13: =IF(ISNUMBER(F13),IF(G13="",VLOOKUP($A13,'Loc Coefficients Config'!$A:$H,8,FALSE),VLOOKUP(G13,'Loc Coefficients Location'!A:E,5,FALSE)),"") | N13: =IF(ISNUMBER(M13),ROUND($F13*M13,2),"") | O13: =IF(ISNUMBER(F13),IF(G13="",VLOOKUP($A13,'Loc Coefficients Config'!$A:$I,9,FALSE),VLOOKUP(G13,'Loc Coefficients Location'!A:F,6,FALSE)),"") | P13: =IF(ISNUMBER(O13),ROUND($F13*O13,2),"")
A14: Garantie 5 ans J+1 châssis | B14: HPE Microserver Gen10 Plus Support | C14: HU4B2A5#YKX | D14: 1 | G14: SOFT/MAINT | H14: =IF(ISNUMBER($F14),ROUND($F14*H$1,2),"") | I14: =IF(ISNUMBER($F14),ROUND($F14*I$1,2),"") | J14: =IF(ISNUMBER($F14),ROUND($F14*J$1,2),"") | K14: =IF(ISNUMBER(F14),IF(G14="",VLOOKUP($A14,'Loc Coefficients Config'!$A:$G,7,FALSE),VLOOKUP(G14,'Loc Coefficients Location'!A:D,4,FALSE)),"") | L14: =IF(ISNUMBER(K14),ROUND($F14*K14,2),"") | M14: =IF(ISNUMBER(F14),IF(G14="",VLOOKUP($A14,'Loc Coefficients Config'!$A:$H,8,FALSE),VLOOKUP(G14,'Loc Coefficients Location'!A:E,5,FALSE)),"") | N14: =IF(ISNUMBER(M14),ROUND($F14*M14,2),"") | O14: =IF(ISNUMBER(F14),IF(G14="",VLOOKUP($A14,'Loc Coefficients Config'!$A:$I,9,FALSE),VLOOKUP(G14,'Loc Coefficients Location'!A:F,6,FALSE)),"") | P14: =IF(ISNUMBER(O14),ROUND($F14*O14,2),"")
H15: =IF(ISNUMBER($F15),ROUND($F15*H$1,2),"") | I15: =IF(ISNUMBER($F15),ROUND($F15*I$1,2),"") | J15: =IF(ISNUMBER($F15),ROUND($F15*J$1,2),"") | K15: =IF(ISNUMBER(F15),IF(G15="",VLOOKUP($A15,'Loc Coefficients Config'!$A:$G,7,FALSE),VLOOKUP(G15,'Loc Coefficients Location'!A:D,4,FALSE)),"") | L15: =IF(ISNUMBER(K15),ROUND($F15*K15,2),"") | M15: =IF(ISNUMBER(F15),IF(G15="",VLOOKUP($A15,'Loc Coefficients Config'!$A:$H,8,FALSE),VLOOKUP(G15,'Loc Coefficients Location'!A:E,5,FALSE)),"") | N15: =IF(ISNUMBER(M15),ROUND($F15*M15,2),"") | O15: =IF(ISNUMBER(F15),IF(G15="",VLOOKUP($A15,'Loc Coefficients Config'!$A:$I,9,FALSE),VLOOKUP(G15,'Loc Coefficients Location'!A:F,6,FALSE)),"") | P15: =IF(ISNUMBER(O15),ROUND($F15*O15,2),"")
A16: Cat1 Conf5 DL20 Gen10 plus | B16: HPE ProLiant DL20 Gen10 plus | C16: P44109-B21 | F16: 310.47 | H16: =IF(ISNUMBER($F16),ROUND($F16*H$1,2),"") -> 83.48 | I16: =IF(ISNUMBER($F16),ROUND($F16*I$1,2),"") -> 42.96 | J16: =IF(ISNUMBER($F16),ROUND($F16*J$1,2),"") -> 29.5 | K16: =IF(ISNUMBER(F16),IF(G16="",VLOOKUP($A16,'Loc Coefficients Config'!$A:$G,7,FALSE),VLOOKUP(G16,'Loc Coefficients Location'!A:D,4,FALSE)),"") -> 0.21791781 | L16: =IF(ISNUMBER(K16),ROUND($F16*K16,2),"") -> 67.66 | M16: =IF(ISNUMBER(F16),IF(G16="",VLOOKUP($A16,'Loc Coefficients Config'!$A:$H,8,FALSE),VLOOKUP(G16,'Loc Coefficients Location'!A:E,5,FALSE)),"") -> 0.11564498 | N16: =IF(ISNUMBER(M16),ROUND($F16*M16,2),"") -> 35.9 | O16: =IF(ISNUMBER(F16),IF(G16="",VLOOKUP($A16,'Loc Coefficients Config'!$A:$I,9,FALSE),VLOOKUP(G16,'Loc Coefficients Location'!A:F,6,FALSE)),"") -> 0.084788504 | P16: =IF(ISNUMBER(O16),ROUND($F16*O16,2),"") -> 26.32
A17: Serveur rack standard 1U DL20 Gen10+ mono-socket INTEL | B17: HPE DL20 Gen10+ 2LFF NHP CTO Svr | C17: P44109-B21 | D17: 1 | G17: PC_SE/PLX86 | H17: =IF(ISNUMBER($F17),ROUND($F17*H$1,2),"") | I17: =IF(ISNUMBER($F17),ROUND($F17*I$1,2),"") | J17: =IF(ISNUMBER($F17),ROUND($F17*J$1,2),"") | K17: =IF(ISNUMBER(F17),IF(G17="",VLOOKUP($A17,'Loc Coefficients Config'!$A:$G,7,FALSE),VLOOKUP(G17,'Loc Coefficients Location'!A:D,4,FALSE)),"") | L17: =IF(ISNUMBER(K17),ROUND($F17*K17,2),"") | M17: =IF(ISNUMBER(F17),IF(G17="",VLOOKUP($A17,'Loc Coefficients Config'!$A:$H,8,FALSE),VLOOKUP(G17,'Loc Coefficients Location'!A:E,5,FALSE)),"") | N17: =IF(ISNUMBER(M17),ROUND($F17*M17,2),"") | O17: =IF(ISNUMBER(F17),IF(G17="",VLOOKUP($A17,'Loc Coefficients Config'!$A:$I,9,FALSE),VLOOKUP(G17,'Loc Coefficients Location'!A:F,6,FALSE)),"") | P17: =IF(ISNUMBER(O17),ROUND($F17*O17,2),"")
A18: Processeur 64 bits Intel Xeon E-2314 (2,8 GHz de base / 4,50 Ghz Turbo / 4 cœurs / 4 threads / 8 Mo Smart Cache / 65W TDP) | B18: Intel Xeon E-2314 FIO CPU for HPE | C18: P45248-B21 | D18: 1 | G18: PC_SE/PLX86 | H18: =IF(ISNUMBER($F18),ROUND($F18*H$1,2),"") | I18: =IF(ISNUMBER($F18),ROUND($F18*I$1,2),"") | J18: =IF(ISNUMBER($F18),ROUND($F18*J$1,2),"") | K18: =IF(ISNUMBER(F18),IF(G18="",VLOOKUP($A18,'Loc Coefficients Config'!$A:$G,7,FALSE),VLOOKUP(G18,'Loc Coefficients Location'!A:D,4,FALSE)),"") | L18: =IF(ISNUMBER(K18),ROUND($F18*K18,2),"") | M18: =IF(ISNUMBER(F18),IF(G18="",VLOOKUP($A18,'Loc Coefficients Config'!$A:$H,8,FALSE),VLOOKUP(G18,'Loc Coefficients Location'!A:E,5,FALSE)),"") | N18: =IF(ISNUMBER(M18),ROUND($F18*M18,2),"") | O18: =IF(ISNUMBER(F18),IF(G18="",VLOOKUP($A18,'Loc Coefficients Config'!$A:$I,9,FALSE),VLOOKUP(G18,'Loc Coefficients Location'!A:F,6,FALSE)),"") | P18: =IF(ISNUMBER(O18),ROUND($F18*O18,2),"")
A19: Barrette mémoire de 16GB HPE Standard DDR4-3200 UDIMM | B19: HPE 16GB 1Rx8 PC4-3200AA-E STND Kit | C19: P43019-B21 | D19: 1 | G19: PC_SE/PLX86 | H19: =IF(ISNUMBER($F19),ROUND($F19*H$1,2),"") | I19: =IF(ISNUMBER($F19),ROUND($F19*I$1,2),"") | J19: =IF(ISNUMBER($F19),ROUND($F19*J$1,2),"") | K19: =IF(ISNUMBER(F19),IF(G19="",VLOOKUP($A19,'Loc Coefficients Config'!$A:$G,7,FALSE),VLOOKUP(G19,'Loc Coefficients Location'!A:D,4,FALSE)),"") | L19: =IF(ISNUMBER(K19),ROUND($F19*K19,2),"") | M19: =IF(ISNUMBER(F19),IF(G19="",VLOOKUP($A19,'Loc Coefficients Config'!$A:$H,8,FALSE),VLOOKUP(G19,'Loc Coefficients Location'!A:E,5,FALSE)),"") | N19: =IF(ISNUMBER(M19),ROUND($F19*M19,2),"") | O19: =IF(ISNUMBER(F19),IF(G19="",VLOOKUP($A19,'Loc Coefficients Config'!$A:$I,9,FALSE),VLOOKUP(G19,'Loc Coefficients Location'!A:F,6,FALSE)),"") | P19: =IF(ISNUMBER(O19),ROUND($F19*O19,2),"")
A20: 1 cage pour emplacement PCI | B20: HPE DL20 Gen10+ 2x8 LP FIO Riser Kit | C20: P46114-B21 | D20: 1 | G20: PC_SE/PLX86 | H20: =IF(ISNUMBER($F20),ROUND($F20*H$1,2),"") | I20: =IF(ISNUMBER($F20),ROUND($F20*I$1,2),"") | J20: =IF(ISNUMBER($F20),ROUND($F20*J$1,2),"") | K20: =IF(ISNUMBER(F20),IF(G20="",VLOOKUP($A20,'Loc Coefficients Config'!$A:$G,7,FALSE),VLOOKUP(G20,'Loc Coefficients Location'!A:D,4,FALSE)),"") | L20: =IF(ISNUMBER(K20),ROUND($F20*K20,2),"") | M20: =IF(ISNUMBER(F20),IF(G20="",VLOOKUP($A20,'Loc Coefficients Config'!$A:$H,8,FALSE),VLOOKUP(G20,'Loc Coefficients Location'!A:E,5,FALSE)),"") | N20: =IF(ISNUMBER(M20),ROUND($F20*M20,2),"") | O20: =IF(ISNUMBER(F20),IF(G20="",VLOOKUP($A20,'Loc Coefficients Config'!$A:$I,9,FALSE),VLOOKUP(G20,'Loc Coefficients Location'!A:F,6,FALSE)),"") | P20: =IF(ISNUMBER(O20),ROUND($F20*O20,2),"")
A21: Alimentation Titanium 800W | B21: HPE 800W FS Ti Ht Plg LH Pwr Sply Kit | C21: 865438-B21 | D21: 1 | G21: PC_SE/PLX86 | H21: =IF(ISNUMBER($F21),ROUND($F21*H$1,2),"") | I21: =IF(ISNUMBER($F21),ROUND($F21*I$1,2),"") | J21: =IF(ISNUMBER($F21),ROUND($F21*J$1,2),"") | K21: =IF(ISNUMBER(F21),IF(G21="",VLOOKUP($A21,'Loc Coefficients Config'!$A:$G,7,FALSE),VLOOKUP(G21,'Loc Coefficients Location'!A:D,4,FALSE)),"") | L21: =IF(ISNUMBER(K21),ROUND($F21*K21,2),"") | M21: =IF(ISNUMBER(F21),IF(G21="",VLOOKUP($A21,'Loc Coefficients Config'!$A:$H,8,FALSE),VLOOKUP(G21,'Loc Coefficients Location'!A:E,5,FALSE)),"") | N21: =IF(ISNUMBER(M21),ROUND($F21*M21,2),"") | O21: =IF(ISNUMBER(F21),IF(G21="",VLOOKUP($A21,'Loc Coefficients Config'!$A:$I,9,FALSE),VLOOKUP(G21,'Loc Coefficients Location'!A:F,6,FALSE)),"") | P21: =IF(ISNUMBER(O21),ROUND($F21*O21,2),"")
A22: Activation Alimentation redondante | B22: HPE ProLiant DL20 Gen10 Plus RPS FIO Enablement Kit | C22: P45948-B21 | D22: Cat | H22: =IF(ISNUMBER($F22),ROUND($F22*H$1,2),"") | I22: =IF(ISNUMBER($F22),ROUND($F22*I$1,2),"") | J22: =IF(ISNUMBER($F22),ROUND($F22*J$1,2),"") | K22: =IF(ISNUMBER(F22),IF(G22="",VLOOKUP($A22,'Loc Coefficients Config'!$A:$G,7,FALSE),VLOOKUP(G22,'Loc Coefficients Location'!A:D,4,FALSE)),"") | L22: =IF(ISNUMBER(K22),ROUND($F22*K22,2),"") | M22: =IF(ISNUMBER(F22),IF(G22="",VLOOKUP($A22,'Loc Coefficients Config'!$A:$H,8,FALSE),VLOOKUP(G22,'Loc Coefficients Location'!A:E,5,FALSE)),"") | N22: =IF(ISNUMBER(M22),ROUND($F22*M22,2),"") | O22: =IF(ISNUMBER(F22),IF(G22="",VLOOKUP($A22,'Loc Coefficients Config'!$A:$I,9,FALSE),VLOOKUP(G22,'Loc Coefficients Location'!A:F,6,FALSE)),"") | P22: =IF(ISNUMBER(O22),ROUND($F22*O22,2),"")
A23: Licence iLO en version Advanced avec toutes les options activées | B23: HPE iLO Adv 1-svr Lic 1yr Support | C23: 512485-B21 | D23: 1 | G23: SOFTCOST | H23: =IF(ISNUMBER($F23),ROUND($F23*H$1,2),"") | I23: =IF(ISNUMBER($F23),ROUND($F23*I$1,2),"") | J23: =IF(ISNUMBER($F23),ROUND($F23*J$1,2),"") | K23: =IF(ISNUMBER(F23),IF(G23="",VLOOKUP($A23,'Loc Coefficients Config'!$A:$G,7,FALSE),VLOOKUP(G23,'Loc Coefficients Location'!A:D,4,FALSE)),"") | L23: =IF(ISNUMBER(K23),ROUND($F23*K23,2),"") | M23: =IF(ISNUMBER(F23),IF(G23="",VLOOKUP($A23,'Loc Coefficients Config'!$A:$H,8,FALSE),VLOOKUP(G23,'Loc Coefficients Location'!A:E,5,FALSE)),"") | N23: =IF(ISNUMBER(M23),ROUND($F23*M23,2),"") | O23: =IF(ISNUMBER(F23),IF(G23="",VLOOKUP($A23,'Loc Coefficients Config'!$A:$I,9,FALSE),VLOOKUP(G23,'Loc Coefficients Location'!A:F,6,FALSE)),"") | P23: =IF(ISNUMBER(O23),ROUND($F23*O23,2),"")
A24: Suppression des câbles électriques par défaut | B24: HPE Remove Standard Power Cords | C24: 469774-409 | D24: 1 | G24: SOFTCOST | H24: =IF(ISNUMBER($F24),ROUND($F24*H$1,2),"") | I24: =IF(ISNUMBER($F24),ROUND($F24*I$1,2),"") | J24: =IF(ISNUMBER($F24),ROUND($F24*J$1,2),"") | K24: =IF(ISNUMBER(F24),IF(G24="",VLOOKUP($A24,'Loc Coefficients Config'!$A:$G,7,FALSE),VLOOKUP(G24,'Loc Coefficients Location'!A:D,4,FALSE)),"") | L24: =IF(ISNUMBER(K24),ROUND($F24*K24,2),"") | M24: =IF(ISNUMBER(F24),IF(G24="",VLOOKUP($A24,'Loc Coefficients Config'!$A:$H,8,FALSE),VLOOKUP(G24,'Loc Coefficients Location'!A:E,5,FALSE)),"") | N24: =IF(ISNUMBER(M24),ROUND($F24*M24,2),"") | O24: =IF(ISNUMBER(F24),IF(G24="",VLOOKUP($A24,'Loc Coefficients Config'!$A:$I,9,FALSE),VLOOKUP(G24,'Loc Coefficients Location'!A:F,6,FALSE)),"") | P24: =IF(ISNUMBER(O24),ROUND($F24*O24,2),"")
A25: 1 kit de rail pour rack | B25: HPE 1U Short Friction Rail Kit | C25: 775612-B21 | D25: 1 | G25: PC_SE/PLX86 | H25: =IF(ISNUMBER($F25),ROUND($F25*H$1,2),"") | I25: =IF(ISNUMBER($F25),ROUND($F25*I$1,2),"") | J25: =IF(ISNUMBER($F25),ROUND($F25*J$1,2),"") | K25: =IF(ISNUMBER(F25),IF(G25="",VLOOKUP($A25,'Loc Coefficients Config'!$A:$G,7,FALSE),VLOOKUP(G25,'Loc Coefficients Location'!A:D,4,FALSE)),"") | L25: =IF(ISNUMBER(K25),ROUND($F25*K25,2),"") | M25: =IF(ISNUMBER(F25),IF(G25="",VLOOKUP($A25,'Loc Coefficients Config'!$A:$H,8,FALSE),VLOOKUP(G25,'Loc Coefficients Location'!A:E,5,FALSE)),"") | N25: =IF(ISNUMBER(M25),ROUND($F25*M25,2),"") | O25: =IF(ISNUMBER(F25),IF(G25="",VLOOKUP($A25,'Loc Coefficients Config'!$A:$I,9,FALSE),VLOOKUP(G25,'Loc Coefficients Location'!A:F,6,FALSE)),"") | P25: =IF(ISNUMBER(O25),ROUND($F25*O25,2),"")
A26: Livraison devant la porte | B26: HPE Door/dock Small Delivery SVC | C26: AC111A | D26: 1 | G26: SOFTCOST | H26: =IF(ISNUMBER($F26),ROUND($F26*H$1,2),"") | I26: =IF(ISNUMBER($F26),ROUND($F26*I$1,2),"") | J26: =IF(ISNUMBER($F26),ROUND($F26*J$1,2),"") | K26: =IF(ISNUMBER(F26),IF(G26="",VLOOKUP($A26,'Loc Coefficients Config'!$A:$G,7,FALSE),VLOOKUP(G26,'Loc Coefficients Location'!A:D,4,FALSE)),"") | L26: =IF(ISNUMBER(K26),ROUND($F26*K26,2),"") | M26: =IF(ISNUMBER(F26),IF(G26="",VLOOKUP($A26,'Loc Coefficients Config'!$A:$H,8,FALSE),VLOOKUP(G26,'Loc Coefficients Location'!A:E,5,FALSE)),"") | N26: =IF(ISNUMBER(M26),ROUND($F26*M26,2),"") | O26: =IF(ISNUMBER(F26),IF(G26="",VLOOKUP($A26,'Loc Coefficients Config'!$A:$I,9,FALSE),VLOOKUP(G26,'Loc Coefficients Location'!A:F,6,FALSE)),"") | P26: =IF(ISNUMBER(O26),ROUND($F26*O26,2),"")
A27: Support 5 ans H+4 ILO | B27: HPE 5Y TC Ess iLO Adv Non BL SVC | C27: HW2P1E | D27: 1 | G27: SOFT/MAINT | H27: =IF(ISNUMBER($F27),ROUND($F27*H$1,2),"") | I27: =IF(ISNUMBER($F27),ROUND($F27*I$1,2),"") | J27: =IF(ISNUMBER($F27),ROUND($F27*J$1,2),"") | K27: =IF(ISNUMBER(F27),IF(G27="",VLOOKUP($A27,'Loc Coefficients Config'!$A:$G,7,FALSE),VLOOKUP(G27,'Loc Coefficients Location'!A:D,4,FALSE)),"") | L27: =IF(ISNUMBER(K27),ROUND($F27*K27,2),"") | M27: =IF(ISNUMBER(F27),IF(G27="",VLOOKUP($A27,'Loc Coefficients Config'!$A:$H,8,FALSE),VLOOKUP(G27,'Loc Coefficients Location'!A:E,5,FALSE)),"") | N27: =IF(ISNUMBER(M27),ROUND($F27*M27,2),"") | O27: =IF(ISNUMBER(F27),IF(G27="",VLOOKUP($A27,'Loc Coefficients Config'!$A:$I,9,FALSE),VLOOKUP(G27,'Loc Coefficients Location'!A:F,6,FALSE)),"") | P27: =IF(ISNUMBER(O27),ROUND($F27*O27,2),"")
A28: Garantie 5 ans J+1 châssis | B28: HPE 5Y TC Bas DL20 Gen10 Plus HW SVC | C28: H32ZWE | D28: 1 | G28: SOFT/MAINT | H28: =IF(ISNUMBER($F28),ROUND($F28*H$1,2),"") | I28: =IF(ISNUMBER($F28),ROUND($F28*I$1,2),"") | J28: =IF(ISNUMBER($F28),ROUND($F28*J$1,2),"") | K28: =IF(ISNUMBER(F28),IF(G28="",VLOOKUP($A28,'Loc Coefficients Config'!$A:$G,7,FALSE),VLOOKUP(G28,'Loc Coefficients Location'!A:D,4,FALSE)),"") | L28: =IF(ISNUMBER(K28),ROUND($F28*K28,2),"") | M28: =IF(ISNUMBER(F28),IF(G28="",VLOOKUP($A28,'Loc Coefficients Config'!$A:$H,8,FALSE),VLOOKUP(G28,'Loc Coefficients Location'!A:E,5,FALSE)),"") | N28: =IF(ISNUMBER(M28),ROUND($F28*M28,2),"") | O28: =IF(ISNUMBER(F28),IF(G28="",VLOOKUP($A28,'Loc Coefficients Config'!$A:$I,9,FALSE),VLOOKUP(G28,'Loc Coefficients Location'!A:F,6,FALSE)),"") | P28: =IF(ISNUMBER(O28),ROUND($F28*O28,2),"")
H29: =IF(ISNUMBER($F29),ROUND($F29*H$1,2),"") | I29: =IF(ISNUMBER($F29),ROUND($F29*I$1,2),"") | J29: =IF(ISNUMBER($F29),ROUND($F29*J$1,2),"") | K29: =IF(ISNUMBER(F29),IF(G29="",VLOOKUP($A29,'Loc Coefficients Config'!$A:$G,7,FALSE),VLOOKUP(G29,'Loc Coefficients Location'!A:D,4,FALSE)),"") | L29: =IF(ISNUMBER(K29),ROUND($F29*K29,2),"") | M29: =IF(ISNUMBER(F29),IF(G29="",VLOOKUP($A29,'Loc Coefficients Config'!$A:$H,8,FALSE),VLOOKUP(G29,'Loc Coefficients Location'!A:E,5,FALSE)),"") | N29: =IF(ISNUMBER(M29),ROUND($F29*M29,2),"") | O29: =IF(ISNUMBER(F29),IF(G29="",VLOOKUP($A29,'Loc Coefficients Config'!$A:$I,9,FALSE),VLOOKUP(G29,'Loc Coefficients Location'!A:F,6,FALSE)),"") | P29: =IF(ISNUMBER(O29),ROUND($F29*O29,2),"")
H30: =IF(ISNUMBER($F30),ROUND($F30*H$1,2),"") | I30: =IF(ISNUMBER($F30),ROUND($F30*I$1,2),"") | J30: =IF(ISNUMBER($F30),ROUND($F30*J$1,2),"") | K30: =IF(ISNUMBER(F30),IF(G30="",VLOOKUP($A30,'Loc Coefficients Config'!$A:$G,7,FALSE),VLOOKUP(G30,'Loc Coefficients Location'!A:D,4,FALSE)),"") | L30: =IF(ISNUMBER(K30),ROUND($F30*K30,2),"") | M30: =IF(ISNUMBER(F30),IF(G30="",VLOOKUP($A30,'Loc Coefficients Config'!$A:$H,8,FALSE),VLOOKUP(G30,'Loc Coefficients Location'!A:E,5,FALSE)),"") | N30: =IF(ISNUMBER(M30),ROUND($F30*M30,2),"") | O30: =IF(ISNUMBER(F30),IF(G30="",VLOOKUP($A30,'Loc Coefficients Config'!$A:$I,9,FALSE),VLOOKUP(G30,'Loc Coefficients Location'!A:F,6,FALSE)),"") | P30: =IF(ISNUMBER(O30),ROUND($F30*O30,2),"")
A31: Cat1 Conf10 DL325 Gen10 plus v2 | B31: HPE ProLiant DL325 Gen10 plus V2 | C31: P38471-B21 | F31: 969.28 | H31: =IF(ISNUMBER($F31),ROUND($F31*H$1,2),"") -> 260.63 | I31: =IF(ISNUMBER($F31),ROUND($F31*I$1,2),"") -> 134.11 | J31: =IF(ISNUMBER($F31),ROUND($F31*J$1,2),"") -> 92.11 | K31: =IF(ISNUMBER(F31),IF(G31="",VLOOKUP($A31,'Loc Coefficients Config'!$A:$G,7,FALSE),VLOOKUP(G31,'Loc Coefficients Location'!A:D,4,FALSE)),"") -> 0.22717399 | L31: =IF(ISNUMBER(K31),ROUND($F31*K31,2),"") -> 220.2 | M31: =IF(ISNUMBER(F31),IF(G31="",VLOOKUP($A31,'Loc Coefficients Config'!$A:$H,8,FALSE),VLOOKUP(G31,'Loc Coefficients Location'!A:E,5,FALSE)),"") -> 0.11977037 | N31: =IF(ISNUMBER(M31),ROUND($F31*M31,2),"") -> 116.09 | O31: =IF(ISNUMBER(F31),IF(G31="",VLOOKUP($A31,'Loc Coefficients Config'!$A:$I,9,FALSE),VLOOKUP(G31,'Loc Coefficients Location'!A:F,6,FALSE)),"") -> 0.086647524 | P31: =IF(ISNUMBER(O31),ROUND($F31*O31,2),"") -> 83.99
A32: Serveur rack standard 1U mono-socket AMD | B32: HPE DL325 G10+ v2 8SFF CTO Svr | C32: P38471-B21 | D32: 1 | G32: PC_SE/PLX86 | H32: =IF(ISNUMBER($F32),ROUND($F32*H$1,2),"") | I32: =IF(ISNUMBER($F32),ROUND($F32*I$1,2),"") | J32: =IF(ISNUMBER($F32),ROUND($F32*J$1,2),"") | K32: =IF(ISNUMBER(F32),IF(G32="",VLOOKUP($A32,'Loc Coefficients Config'!$A:$G,7,FALSE),VLOOKUP(G32,'Loc Coefficients Location'!A:D,4,FALSE)),"") | L32: =IF(ISNUMBER(K32),ROUND($F32*K32,2),"") | M32: =IF(ISNUMBER(F32),IF(G32="",VLOOKUP($A32,'Loc Coefficients Config'!$A:$H,8,FALSE),VLOOKUP(G32,'Loc Coefficients Location'!A:E,5,FALSE)),"") | N32: =IF(ISNUMBER(M32),ROUND($F32*M32,2),"") | O32: =IF(ISNUMBER(F32),IF(G32="",VLOOKUP($A32,'Loc Coefficients Config'!$A:$I,9,FALSE),VLOOKUP(G32,'Loc Coefficients Location'!A:F,6,FALSE)),"") | P32: =IF(ISNUMBER(O32),ROUND($F32*O32,2),"")
A33: Processeur 64 bits AMD EPYC 7232P (3,1 GHz de base 8 cœurs / 16 threads) | B33: AMD EPYC 7232P Kit for DL325 Gen10+ v2 | C33: P39738-B21 | D33: 1 | G33: PC_SE/PLX86 | H33: =IF(ISNUMBER($F33),ROUND($F33*H$1,2),"") | I33: =IF(ISNUMBER($F33),ROUND($F33*I$1,2),"") | J33: =IF(ISNUMBER($F33),ROUND($F33*J$1,2),"") | K33: =IF(ISNUMBER(F33),IF(G33="",VLOOKUP($A33,'Loc Coefficients Config'!$A:$G,7,FALSE),VLOOKUP(G33,'Loc Coefficients Location'!A:D,4,FALSE)),"") | L33: =IF(ISNUMBER(K33),ROUND($F33*K33,2),"") | M33: =IF(ISNUMBER(F33),IF(G33="",VLOOKUP($A33,'Loc Coefficients Config'!$A:$H,8,FALSE),VLOOKUP(G33,'Loc Coefficients Location'!A:E,5,FALSE)),"") | N33: =IF(ISNUMBER(M33),ROUND($F33*M33,2),"") | O33: =IF(ISNUMBER(F33),IF(G33="",VLOOKUP($A33,'Loc Coefficients Config'!$A:$I,9,FALSE),VLOOKUP(G33,'Loc Coefficients Location'!A:F,6,FALSE)),"") | P33: =IF(ISNUMBER(O33),ROUND($F33*O33,2),"")
A34: Barrette mémoire de 32GB HPE DDR4-3200 RDIMM | B34: HPE 32GB 2Rx4 PC4-3200AA-R Smart Kit | C34: P07646-B21 | D34: 1 | G34: PC_SE/PLX86 | H34: =IF(ISNUMBER($F34),ROUND($F34*H$1,2),"") | I34: =IF(ISNUMBER($F34),ROUND($F34*I$1,2),"") | J34: =IF(ISNUMBER($F34),ROUND($F34*J$1,2),"") | K34: =IF(ISNUMBER(F34),IF(G34="",VLOOKUP($A34,'Loc Coefficients Config'!$A:$G,7,FALSE),VLOOKUP(G34,'Loc Coefficients Location'!A:D,4,FALSE)),"") | L34: =IF(ISNUMBER(K34),ROUND($F34*K34,2),"") | M34: =IF(ISNUMBER(F34),IF(G34="",VLOOKUP($A34,'Loc Coefficients Config'!$A:$H,8,FALSE),VLOOKUP(G34,'Loc Coefficients Location'!A:E,5,FALSE)),"") | N34: =IF(ISNUMBER(M34),ROUND($F34*M34,2),"") | O34: =IF(ISNUMBER(F34),IF(G34="",VLOOKUP($A34,'Loc Coefficients Config'!$A:$I,9,FALSE),VLOOKUP(G34,'Loc Coefficients Location'!A:F,6,FALSE)),"") | P34: =IF(ISNUMBER(O34),ROUND($F34*O34,2),"")
A35: Cage disque 8SFF | B35: HPE ProLiant DL325 Gen10 Plus v2 8SFF SAS/SATA BC FIO Backplane Kit | C35: P38473-B21 | D35: 1 | G35: PC_SE/PLX86 | H35: =IF(ISNUMBER($F35),ROUND($F35*H$1,2),"") | I35: =IF(ISNUMBER($F35),ROUND($F35*I$1,2),"") | J35: =IF(ISNUMBER($F35),ROUND($F35*J$1,2),"") | K35: =IF(ISNUMBER(F35),IF(G35="",VLOOKUP($A35,'Loc Coefficients Config'!$A:$G,7,FALSE),VLOOKUP(G35,'Loc Coefficients Location'!A:D,4,FALSE)),"") | L35: =IF(ISNUMBER(K35),ROUND($F35*K35,2),"") | M35: =IF(ISNUMBER(F35),IF(G35="",VLOOKUP($A35,'Loc Coefficients Config'!$A:$H,8,FALSE),VLOOKUP(G35,'Loc Coefficients Location'!A:E,5,FALSE)),"") | N35: =IF(ISNUMBER(M35),ROUND($F35*M35,2),"") | O35: =IF(ISNUMBER(F35),IF(G35="",VLOOKUP($A35,'Loc Coefficients Config'!$A:$I,9,FALSE),VLOOKUP(G35,'Loc Coefficients Location'!A:F,6,FALSE)),"") | P35: =IF(ISNUMBER(O35),ROUND($F35*O35,2),"")
A36: 2 ports Ethernet 10GbE Base-T OCP (intégré) | B36: BCM 57416 10GbE 2p BASE-T OCP3 Adptr | C36: P10097-B21 | D36: 1 | G36: PC_SE/PLX86 | H36: =IF(ISNUMBER($F36),ROUND($F36*H$1,2),"") | I36: =IF(ISNUMBER($F36),ROUND($F36*I$1,2),"") | J36: =IF(ISNUMBER($F36),ROUND($F36*J$1,2),"") | K36: =IF(ISNUMBER(F36),IF(G36="",VLOOKUP($A36,'Loc Coefficients Config'!$A:$G,7,FALSE),VLOOKUP(G36,'Loc Coefficients Location'!A:D,4,FALSE)),"") | L36: =IF(ISNUMBER(K36),ROUND($F36*K36,2),"") | M36: =IF(ISNUMBER(F36),IF(G36="",VLOOKUP($A36,'Loc Coefficients Config'!$A:$H,8,FALSE),VLOOKUP(G36,'Loc Coefficients Location'!A:E,5,FALSE)),"") | N36: =IF(ISNUMBER(M36),ROUND($F36*M36,2),"") | O36: =IF(ISNUMBER(F36),IF(G36="",VLOOKUP($A36,'Loc Coefficients Config'!$A:$I,9,FALSE),VLOOKUP(G36,'Loc Coefficients Location'!A:F,6,FALSE)),"") | P36: =IF(ISNUMBER(O36),ROUND($F36*O36,2),"")
A37: Alimentation Titanium 800W | B37: HPE 800W FS Ti Ht Plg LH Pwr Sply Kit | C37: 865438-B21 | D37: 1 | G37: PC_SE/PLX86 | H37: =IF(ISNUMBER($F37),ROUND($F37*H$1,2),"") | I37: =IF(ISNUMBER($F37),ROUND($F37*I$1,2),"") | J37: =IF(ISNUMBER($F37),ROUND($F37*J$1,2),"") | K37: =IF(ISNUMBER(F37),IF(G37="",VLOOKUP($A37,'Loc Coefficients Config'!$A:$G,7,FALSE),VLOOKUP(G37,'Loc Coefficients Location'!A:D,4,FALSE)),"") | L37: =IF(ISNUMBER(K37),ROUND($F37*K37,2),"") | M37: =IF(ISNUMBER(F37),IF(G37="",VLOOKUP($A37,'Loc Coefficients Config'!$A:$H,8,FALSE),VLOOKUP(G37,'Loc Coefficients Location'!A:E,5,FALSE)),"") | N37: =IF(ISNUMBER(M37),ROUND($F37*M37,2),"") | O37: =IF(ISNUMBER(F37),IF(G37="",VLOOKUP($A37,'Loc Coefficients Config'!$A:$I,9,FALSE),VLOOKUP(G37,'Loc Coefficients Location'!A:F,6,FALSE)),"") | P37: =IF(ISNUMBER(O37),ROUND($F37*O37,2),"")
A38: Licence iLO en version Advanced avec toutes les options activées | B38: HPE iLO Adv 1-svr Lic 1yr Support | C38: 512485-B21 | D38: 1 | G38: SOFTCOST | H38: =IF(ISNUMBER($F38),ROUND($F38*H$1,2),"") | I38: =IF(ISNUMBER($F38),ROUND($F38*I$1,2),"") | J38: =IF(ISNUMBER($F38),ROUND($F38*J$1,2),"") | K38: =IF(ISNUMBER(F38),IF(G38="",VLOOKUP($A38,'Loc Coefficients Config'!$A:$G,7,FALSE),VLOOKUP(G38,'Loc Coefficients Location'!A:D,4,FALSE)),"") | L38: =IF(ISNUMBER(K38),ROUND($F38*K38,2),"") | M38: =IF(ISNUMBER(F38),IF(G38="",VLOOKUP($A38,'Loc Coefficients Config'!$A:$H,8,FALSE),VLOOKUP(G38,'Loc Coefficients Location'!A:E,5,FALSE)),"") | N38: =IF(ISNUMBER(M38),ROUND($F38*M38,2),"") | O38: =IF(ISNUMBER(F38),IF(G38="",VLOOKUP($A38,'Loc Coefficients Config'!$A:$I,9,FALSE),VLOOKUP(G38,'Loc Coefficients Location'!A:F,6,FALSE)),"") | P38: =IF(ISNUMBER(O38),ROUND($F38*O38,2),"")
A39: Outil d'administration | B39: HPE GreenLake COM En 5y Up ProLiant aaS | C39: R7A12AAE | D39: 1 | G39: SOFT/SFT | H39: =IF(ISNUMBER($F39),ROUND($F39*H$1,2),"") | I39: =IF(ISNUMBER($F39),ROUND($F39*I$1,2),"") | J39: =IF(ISNUMBER($F39),ROUND($F39*J$1,2),"") | K39: =IF(ISNUMBER(F39),IF(G39="",VLOOKUP($A39,'Loc Coefficients Config'!$A:$G,7,FALSE),VLOOKUP(G39,'Loc Coefficients Location'!A:D,4,FALSE)),"") | L39: =IF(ISNUMBER(K39),ROUND($F39*K39,2),"") | M39: =IF(ISNUMBER(F39),IF(G39="",VLOOKUP($A39,'Loc Coefficients Config'!$A:$H,8,FALSE),VLOOKUP(G39,'Loc Coefficients Location'!A:E,5,FALSE)),"") | N39: =IF(ISNUMBER(M39),ROUND($F39*M39,2),"") | O39: =IF(ISNUMBER(F39),IF(G39="",VLOOKUP($A39,'Loc Coefficients Config'!$A:$I,9,FALSE),VLOOKUP(G39,'Loc Coefficients Location'!A:F,6,FALSE)),"") | P39: =IF(ISNUMBER(O39),ROUND($F39*O39,2),"")
A40: Kit de câble SATA | B40: HPE DL325 G10+ v2 SATA FIO Cbl Kit | C40: P39134-B21 | D40: 1 | G40: PC_SE/PLX86 | H40: =IF(ISNUMBER($F40),ROUND($F40*H$1,2),"") | I40: =IF(ISNUMBER($F40),ROUND($F40*I$1,2),"") | J40: =IF(ISNUMBER($F40),ROUND($F40*J$1,2),"") | K40: =IF(ISNUMBER(F40),IF(G40="",VLOOKUP($A40,'Loc Coefficients Config'!$A:$G,7,FALSE),VLOOKUP(G40,'Loc Coefficients Location'!A:D,4,FALSE)),"") | L40: =IF(ISNUMBER(K40),ROUND($F40*K40,2),"") | M40: =IF(ISNUMBER(F40),IF(G40="",VLOOKUP($A40,'Loc Coefficients Config'!$A:$H,8,FALSE),VLOOKUP(G40,'Loc Coefficients Location'!A:E,5,FALSE)),"") | N40: =IF(ISNUMBER(M40),ROUND($F40*M40,2),"") | O40: =IF(ISNUMBER(F40),IF(G40="",VLOOKUP($A40,'Loc Coefficients Config'!$A:$I,9,FALSE),VLOOKUP(G40,'Loc Coefficients Location'!A:F,6,FALSE)),"") | P40: =IF(ISNUMBER(O40),ROUND($F40*O40,2),"")
...

Sheet Loc Coefficients Crédit-Bail
A1: Category | B1: Equipment | C1: Type | D1: LRF12 | E1: LRF24 | F1: LRF36 | G1: LRF48
A2: PC_SE/PLX86 | B2: HPE ISS Servers (Apollo; SGI; Synergy; Superdome Flex; StoreEasy; Non Stop, Cloudline) | C2: Server | D2: 0.26888624 | E2: 0.13836099 | F2: 0.095025056 | G2: n/a
A3: PC_SE/EDGE | B3: Edgeline/Moonshot | C3: Server | D3: 0.26888624 | E3: 0.13836099 | F3: 0.095025056 | G3: n/a
A4: Store/PRIMERA | B4: Primera, Nimble and Alletra Storage Hardware; and Store SAN; includes MSA, Store Virtual, IAP(RISS), Storeonce, BX(VLS) | C4: Storage | D4: 0.26888624 | E4: 0.13836099 | F4: 0.095025056 | G4: n/a
A5: Store/DTL | B5: StoreEver MSL and ESL Tape Libraries | C5: Storage | D5: 0.26888624 | E5: 0.13836099 | F5: 0.095025056 | G5: n/a
A6: Store/Other | B6: 3rd Party Storage (EMC Storage, IBM, Lenovo, Pure Storage, Net App) & NAS Storage Appliance (Cisco NSS, QNAP) | C6: Storage | D6: 0.26888624 | E6: 0.13836099 | F6: 0.095025056 | G6: n/a
A7: Netwo/HPEN | B7: Aruba Data Center Networking, Cisco & Arista | C7: Networking | D7: 0.26888624 | E7: 0.13836099 | F7: 0.095025056 | G7: n/a
A8: Netwo/ARUBA | B8: Aruba Wireless | C8: Networking | D8: 0.26888624 | E8: 0.13836099 | F8: 0.095025056 | G8: n/a
A9: SOFTCOST | B9: soft cost | C9: SOFT | D9: 0.26888624 | E9: 0.13836099 | F9: 0.095025056 | G9: n/a
A10: SOFT/MAINT | B10: soft cost | C10: SOFT | D10: =D9 -> 0.26888624 | E10: =E9 -> 0.13836099 | F10: =F9 -> 0.095025056 | G10: =G9 -> n/a

Sheet Loc Coefficients Location
A1: Category | B1: Equipment | C1: Type | D1: LRF12 | E1: LRF24 | F1: LRF36 | G1: LRF48
